Workbook
Name activity_cost: [1]マスタ!$F$4
Name Career_Track: '[2]Career Track '!$A$2:$A$7
Name Cost_Center: '[2]Cost Center'!$A$2:$A$628
Name Deployed_to_Entity: '[2]Deployed-to Entity'!$A$2:$A$69
Name Level: [2]Level!$A$3:$A$13
Name Organization_Unit: '[2]Organization Unit'!$A$2:$A$630
Name SV: '[3]99_List'!$H$4:$H$10
Name アサインチーム: #REF!
Name サービス: #REF!
Name サービステーブル: #REF!
Name サービス一覧: #REF!
Name サービス管理番号: #REF!
Name チームラベリング: [4]List!$F$3:$H$47
Name チームラベリング設定: #REF!
Name フラグ: #REF!
Name 案件種別: [5]List!$A$3:$A$4
Name 案件種別: #REF!
Name 改善案件: #REF!
Name 拠点: [6]!tbl拠点情報[拠点]
Name 公休: [4]List!$C$3:$C$8
Name 公休検索: [4]List!$C$3:$D$8
Name 使用する: [5]List!$F$3:$F$4
Name 使用する: #REF!
Name 所属チーム: [4]List!$A$3:$A$5
Name 組織: '[7]CCJ管理用(記入不要)'!#REF!
Name 担当: #REF!
Name 担当グループ: [8]List!#REF!
Name 担当拠点: [5]List!$K$3:$K$7
Name 担当拠点: #REF!
Name 担当業務: [4]List!$B$3:$B$5
Name 判断基準: [4]習熟度!$C$2:$C$5
Name 非稼働日: #REF!
Name 頻度: [5]List!$E$3:$E$12
Name 頻度: #REF!
Name 返信方法: [5]List!$J$3:$J$5
Name 返信方法: #REF!
Name 優先度: #REF!
Name 有無: [5]List!$G$3:$G$6
Name 有無: #REF!
Name 立川: #REF!

Sheet Update History
B1: ***Highly Confidential. Not To Be Distributed Further Without Authorization of the Sender.***
B2: PJT・サテライト内のみ共有可
B3: Update History | H3: e
B4: Document History | H4: e
B5: Ver. | C5: Date | D5: Created/Updated by (Team, EID) | E5: Update contents | F5: Reviewed by (EID) | G5: Approved by (EID) | H5: e
B6: 1 | C6: 46182 | D6: PwD雇用促進PJT 運用企画T satomi.taguchi | E6: ・新規作成 | F6: shunya.furukawa tetsuyo.yonemura | G6: michiko.sone | H6: e
H7: e
H8: e
H9: e
H10: e
H11: e
H12: e
H13: e
H14: e
H15: e
H16: e
H17: e
H18: e
... H25: e
A26: e | B26: e | C26: e | D26: e | E26: e | F26: e | G26: e

Sheet 使い方ガイド
B1: ***Highly Confidential. Not To Be Distributed Further Without Authorization of the Sender. *** Copyright © 2026 Accenture. All rights reserved.
B2: PJT・サテライトのみ共有可
B3: 全員必ずお読みください！
B4: 本Excel使い方ガイド
B6: 前提： | C6: ①チーム毎に本Excelフォーマットを使って、SV/案件担当者の方より、案件・タスク管理をいただきます。
C7: ∟案件管理は本フォーマットを使うことを必須とします。
C8: ∟タスク管理は本フォーマットを使うか、各チームで既に使っている管理シートがあればそちらを使うでも構いません。
C9: 別途担当者への振り出し・進捗確認・完了やり取りは、これまで通りTeams専用チャネルを活用ください。
C10: 右記、概要説明会スライド参照
C12: ②チーム毎の過去のサービス/案件/タスク情報を反映した案件管理Excelは、PJTより現行BI[OrderList]からエクスポートの上、6月上~中旬頃断面版で配布予定です。
B14: [案件管理マスタ]シート
B15: 対象 | C15: 案件・タスクを管理するSV・案件管理担当者
C16: （案件・タスクの全体進捗状況を確認したいメンバ向け）
B17: 役割 | C17: 案件・タスクの進捗状況管理
B18: 更新者 | C18: SV・案件管理担当者
B19: 使い方 | C19: 新運用開始前(~6末)： | D19: 各チームでサービス/案件/（タスク）情報を最新化する ※PJTで6月上~中旬頃の断面版は配布予定
B20: 使い方 | C20: 新運用開始後(7/1~)： | D20: 常時：[案件管理マスタ]の折りたたみ（4～9行目）のガイドに沿って入力・管理をする
D21: 適宜：サービス情報に更新がある際は、最新のサービス情報マスタを[サービス情報マスタcopy]シートに転記する
B23: [マイタスク]シート
B24: 対象 | C24: 自分が対応するタスク情報のみを抽出して確認したい方
C25: ※本Excelの[案件・タスク版]でタスク管理する場合のみ使用できます。
B26: 役割 | C26: 自分のタスク一覧の確認
B27: 更新者 | C27: 全員
B28: 使い方 | C28: 前提： | D28: 本シートはExcelをダウンロードの上ローカル環境で使用ください（複数名同時に操作によるバッティングを防ぐため）
C29: 手順①： | D29: [マイタスク]シートを開く
C30: 手順②： | D30: U5セル（青いセル）に自分のEIDを入力する
D31: →自分が関わるタスクが自動で一覧表示される
C32: 手順③： | D32: 「自分の役割」列で作業者・ピアレビュー者・SVレビュー者のどれかを確認する

Sheet 案件管理マスタ_案件のみ版
B1: ***Highly Confidential. Not To Be Distributed Further Without Authorization of the Sender. *** Copyright © 2026 Accenture. All rights reserved.
B2: PJT・サテライトのみ共有可
B3: 更新頻度：日次でメンテナンスをお願いします。 | L3: e
C4: 【前提】 | L4: e
C5: ・案件管理は本フォーマットを使うことを必須とします。（全チームが必ず使う列を★で示していますので、必ず入力ください） | L5: e
C6: ・タスク管理は本フォーマットを使うか（[案件・タスク版]シート★以降の列）、各チームで既に使っている管理シートがあればそちらを使うでも構いません。 | L6: e
C7: 【SV・案件管理担当者による対応事項】 | L7: e
C8: サービス情報マスタより対象のサービス管理番号を転記する | D8: ー （サービス管理番号に応じて、サービス情報マスタcopyシートより、サービス名が自動反映される） | E8: 関数で採番された番号をダブルチェックの上、コピーし、値で貼り付けする ※過去の案件番号を参照し自動で番号が振りあてられるので、正しい採番かを再確認する ※その上で案件番号を値で貼り付けする（関数のままだと、過去の完了案件情報を消した際に採番が変わってしまうため） | F8: 対象案件の作業マニュアルで案内されているルールに沿って案件名を決める＆記載する | G8: チーム名を記載する（基本チーム毎のExcel管理を想定）チーム横断の場合の方針は下記参照 | H8: プルダウン選択 | I8: ー （作業実行者の実績開始日が自動反映される） ※本フォーマットでタスク管理を行わない場合は、関数を解除の上手入力ください。 | J8: ・依頼元レビューが完了した日(AD列)を入力する ・依頼元レビューがない場合は、SVレビューが完了し、全ての内部レビューが完了した日を入力する ※日付を入力するとグレーアウトされる | L8: e
L9: e
B10: 青字：関数で自動反映 | L10: e
B11: 必須： | C11: ★ | D11: ★ | E11: ★ | F11: ★ | G11: ★ | H11: ★ | I11: ★ | J11: ★ | L11: e
B12: # | C12: サービス管理番号 | D12: サービス名 | E12: 案件番号 | F12: 案件名 | G12: チーム(案件) | H12: 案件ステータス | I12: 案件デリバリ開始日 | J12: 案件デリバリ完了日 | K12: 採番用(触らない) | L12: e
B13: 1 | C13: A0098 | D13: HR_myTIM/OTデータ作成(Google) | E13: A0098-0032 | F13: 【OT】HR_myTIM/OTデータ作成(Google) 12月度 | G13: 生麦X | H13: デリバリ完了 | I13: 0 | K13: =VALUE(RIGHT($E13,4)) -> 32 | L13: e
B14: 2 | C14: P1999 | D14: テスト運用サービス(SN) | E14: P1999-0073 | F14: 【テスト運用】HPS_JPiT月次基盤資料作成 | G14: 生麦X | H14: デリバリ完了 | I14: 0 | K14: =VALUE(RIGHT($E14,4)) -> 73 | L14: e
B15: 3 | C15: P3999 | D15: テスト運用サービス・データ計測不可(共通) | E15: P3999-1986 | F15: 【杉山さん】ツール練習 | G15: 生麦X | H15: デリバリ完了 | I15: 0 | K15: =VALUE(RIGHT($E15,4)) -> 1986 | L15: e
B16: 4 | C16: A1031 | D16: I&D_Women's stories記事配信 | E16: A1031-0279 | F16: I&D_Women's stories記事配信 英訳追加① No1～7 | G16: 生麦X | H16: タスク進行中 | I16: 0 | K16: =VALUE(RIGHT($E16,4)) -> 279 | L16: e
B17: 5 | C17: A1031 | D17: I&D_Women's stories記事配信 | E17: A1031-0280 | F17: I&D_Women's stories記事配信 英訳追加② No8～13 | G17: 生麦X | H17: 内部完了 | I17: 0 | K17: =VALUE(RIGHT($E17,4)) -> 280 | L17: e
B18: 6 | C18: P1999 | D18: テスト運用サービス(SN) | E18: P1999-0011 | F18: IC-Energy_石油3社のプレスリリース__日経News情報11/24週テスト運用① | G18: 生麦X | H18: デリバリ完了 | I18: 0 | K18: =VALUE(RIGHT($E18,4)) -> 11 | L18: e
B19: 7 | C19: A1025 | D19: 人事異動・組織改編情報チェック(自動化) | E19: A1025-0880 | F19: Nトレーニング人事異動（佐藤さん）⑦ | G19: 生麦X | H19: デリバリ完了 | I19: 0 | K19: =VALUE(RIGHT($E19,4)) -> 880 | L19: e
B20: 8 | C20: A1025 | D20: 人事異動・組織改編情報チェック(自動化) | E20: A1025-0881 | F20: Nトレーニング人事異動（佐藤さん）⑦ | G20: 生麦X | H20: デリバリ完了 | I20: 0 | K20: =VALUE(RIGHT($E20,4)) -> 881 | L20: e
B21: 9 | C21: P3999 | D21: テスト運用サービス・データ計測不可(共通) | E21: P3999-1701 | F21: Nトレーニング人事異動（佐藤さん）⑦ | G21: 生麦X | H21: デリバリ完了 | I21: 0 | K21: =VALUE(RIGHT($E21,4)) -> 1701 | L21: e
B22: 10 | C22: P3999 | D22: テスト運用サービス・データ計測不可(共通) | E22: P3999-1705 | F22: Nトレーニング人事異動（佐藤さん）⑦ | G22: 生麦X | H22: デリバリ完了 | I22: 0 | K22: =VALUE(RIGHT($E22,4)) -> 1705 | L22: e
B23: 11 | C23: P3999 | D23: テスト運用サービス・データ計測不可(共通) | E23: P3999-1702 | F23: Nトレーニング人事異動（山岸さん）⑦ | G23: 生麦X | H23: デリバリ完了 | I23: 0 | K23: =VALUE(RIGHT($E23,4)) -> 1702 | L23: e
B24: 12 | C24: P3999 | D24: テスト運用サービス・データ計測不可(共通) | E24: P3999-1704 | F24: Nトレーニング人事異動（山岸さん）⑦ | G24: 生麦X | H24: デリバリ完了 | I24: 0 | K24: =VALUE(RIGHT($E24,4)) -> 1704 | L24: e
... B92: 80 | C92: A0098 | D92: HR_myTIM/OTデータ作成(Google) | E92: A0098-0004 | F92: 【myTIM】HR_myTIM/OTデータ作成(Google) 7/7週 | G92: 生麦X | H92: デリバリ完了 | I92: 0 | K92: =VALUE(RIGHT($E92,4)) -> 4 | L92: e
B93: 81 | C93: A0098 | D93: HR_myTIM/OTデータ作成(Google) | E93: A0098-0012 | F93: 【myTIM】HR_myTIM/OTデータ作成(Google) 8/18週 | G93: 生麦X | H93: デリバリ完了 | K93: =VALUE(RIGHT($E93,4)) -> 12 | L93: e
B94: 82 | C94: A0098 | D94: HR_myTIM/OTデータ作成(Google) | E94: A0098-0013 | F94: 【myTIM】HR_myTIM/OTデータ作成(Google) 8/18週 | G94: 生麦X | H94: デリバリ完了 | K94: =VALUE(RIGHT($E94,4)) -> 13 | L94: e
B95: 83 | C95: A0098 | D95: HR_myTIM/OTデータ作成(Google) | E95: A0098-0010 | F95: 【myTIM】HR_myTIM/OTデータ作成(Google) 8/4週 | G95: 生麦X | H95: デリバリ完了 | K95: =VALUE(RIGHT($E95,4)) -> 10 | L95: e
B96: 84 | C96: A0098 | D96: HR_myTIM/OTデータ作成(Google) | E96: A0098-0017 | F96: 【myTIM】HR_myTIM/OTデータ作成(Google) 9/15週 | G96: 生麦X | H96: デリバリ完了 | K96: =VALUE(RIGHT($E96,4)) -> 17 | L96: e
B97: 85 | C97: A0098 | D97: HR_myTIM/OTデータ作成(Google) | E97: A0098-0014 | F97: 【myTIM】HR_myTIM/OTデータ作成(Google) 9/1週 | G97: 生麦X | H97: デリバリ完了 | K97: =VALUE(RIGHT($E97,4)) -> 14 | L97: e
B98: 86 | C98: A0098 | D98: HR_myTIM/OTデータ作成(Google) | E98: A0098-0018 | F98: 【myTIM】HR_myTIM/OTデータ作成(Google) 9/22週 | G98: 生麦X | H98: デリバリ完了 | K98: =VALUE(RIGHT($E98,4)) -> 18 | L98: e
B99: 87 | C99: A0098 | D99: HR_myTIM/OTデータ作成(Google) | E99: A0098-0019 | F99: 【myTIM】HR_myTIM/OTデータ作成(Google) 9/29週 | G99: 生麦X | H99: デリバリ完了 | K99: =VALUE(RIGHT($E99,4)) -> 19 | L99: e
B100: 88 | C100: A0098 | D100: HR_myTIM/OTデータ作成(Google) | E100: A0098-0015 | F100: 【myTIM】HR_myTIM/OTデータ作成(Google) 9/8週 | G100: 生麦X | H100: デリバリ完了 | K100: =VALUE(RIGHT($E100,4)) -> 15 | L100: e
B101: 89 | C101: P3000 | D101: 改善案件(共通) | E101: P3000-0658 | F101: 【myTIM】HR_myTIM/OTデータ作成(Google) マニュアル修正 | G101: 生麦X | H101: デリバリ完了 | K101: =VALUE(RIGHT($E101,4)) -> 658 | L101: e
B102: 90 | C102: P3000 | D102: 改善案件(共通) | E102: P3000-0838 | F102: 【myTIM】HR_myTIM/OTデータ作成(Google) マニュアル修正 | G102: 生麦X | H102: デリバリ完了 | K102: =VALUE(RIGHT($E102,4)) -> 838 | L102: e
B103: 91 | C103: P3000 | D103: 改善案件(共通) | E103: P3000-0714 | F103: 【myTIM】HR_myTIM/OTデータ作成(Google) マニュアル改定 | G103: 生麦X | H103: デリバリ完了 | K103: =VALUE(RIGHT($E103,4)) -> 714 | L103: e
B104: 92 | C104: P3000 | D104: 改善案件(共通) | E104: P3000-0415 | F104: 【myTIM】マニュアル見直し | G104: 生麦X | H104: デリバリ完了 | K104: =VALUE(RIGHT($E104,4)) -> 415 | L104: e
... B4165: 4153 | C4165: P3999 | D4165: テスト運用サービス・データ計測不可(共通) | E4165: P3999-1700 | F4165: 起票練習用 | G4165: 生麦X | H4165: デリバリ完了 | K4165: =VALUE(RIGHT($E4165,4)) -> 1700 | L4165: e
B4166: 4154 | D4166: =_xlfn.XLOOKUP($C4166,サービス情報マスタcopy!$B:$B,サービス情報マスタcopy!$G:$G,0,0,1) -> 0 | E4166: =CONCATENATE($C4166,"-",TEXT(_xlfn.MAXIFS($K$12:K4165,$C$12:C4165,$C4166)+1,"0000")) -> -0001 | K4166: =VALUE(RIGHT($E4166,4)) -> 1 | L4166: e
B4167: 4155 | D4167: =_xlfn.XLOOKUP($C4167,サービス情報マスタcopy!$B:$B,サービス情報マスタcopy!$G:$G,0,0,1) -> 0 | E4167: =CONCATENATE($C4167,"-",TEXT(_xlfn.MAXIFS($K$12:K4166,$C$12:C4166,$C4167)+1,"0000")) -> -0001 | K4167: =VALUE(RIGHT($E4167,4)) -> 1 | L4167: e
...

Sheet 案件管理マスタ_案件・タスク版
B1: ***Highly Confidential. Not To Be Distributed Further Without Authorization of the Sender. *** Copyright © 2026 Accenture. All rights reserved.
B2: PJT・サテライトのみ共有可
B3: 更新頻度：日次でメンテナンスをお願いします。 | AG3: e
C4: 【前提】 | AG4: e
C5: ・案件管理は本フォーマットを使うことを必須とします。（全チームが必ず使う列を★で示していますので、必ず入力ください） | AG5: e
C6: ・タスク管理は本フォーマットを使うか（本シート★以降の列）、各チームで既に使っている管理シートがあればそちらを使うでも構いません。 | AG6: e
C7: 【SV・案件管理担当者による対応事項】 | AG7: e
C8: サービス情報マスタより対象のサービス管理番号を転記する | D8: ー （サービス管理番号に応じて、サービス情報マスタcopyシートより、サービス名が自動反映される） | E8: 関数で採番された番号をダブルチェックの上、コピーし、値で貼り付けする ※過去の案件番号を参照し自動で番号が振りあてられるので、正しい採番かを再確認する ※その上で案件番号を値で貼り付けする（関数のままだと、過去の完了案件情報を消した際に採番が変わってしまうため） | F8: 対象案件の作業マニュアルで案内されているルールに沿って案件名を決める＆記載する | G8: チーム名を記載する（基本チーム毎のExcel管理を想定）チーム横断の場合の方針は下記参照 | H8: プルダウン選択 | I8: ー （作業実行者の実績開始日が自動反映される） ※本フォーマットでタスク管理を行わない場合は、関数を解除の上手入力ください。 | J8: ・依頼元レビューが完了した日(AD列)を入力する ・依頼元レビューがない場合は、SVレビューが完了し、全ての内部レビューが完了した日を入力する ※日付を入力するとグレーアウトされる | K8: 過去の採番履歴を確認し、昇順でタスク番号を振る 例)最初のタスクであれば：サービス管理番号-案件番号-01 例)過去のタスクがあれば：サービス管理番号-案件番号-最終番号＋1 | L8: 対象案件の作業マニュアルで案内されているルールに沿ってタスク名を決める＆記載する | M8: プルダウンで選択 | N8: 対象者のEIDを入力する | O8: 実行作業者の開始予定日を入力する | P8: 実行作業者の完了予定日を入力する | Q8: 実行作業者の実際の開始日を入力する ※Teams専用チャネルにてメンバのステータスを確認 ※予定日を超えると赤色で表示されます | R8: 実行作業者の実際の完了日を入力する ※Teams専用チャネルにてメンバのステータスを確認 ※予定日を超えると赤色で表示されます | S8: 対象者のEIDを入力する | T8: ー （実行作業者の予定完了日が自動反映される） | U8: ピアレビュー者の完了予定日を入力する | V8: ピアレビュー者の実際の開始日を入力する ※Teams専用チャネルにてメンバのステータスを確認 ※予定日を超えると赤色で表示されます | W8: ピアレビュー者の実際の完了日を入力する ※Teams専用チャネルにてメンバのステータスを確認 ※予定日を超えると赤色で表示されます | X8: 対象者のEIDを入力する | Y8: ー （ピアレビュー者の予定完了日が自動反映される） | Z8: SVレビュー者の完了予定日を入力する | AA8: SVレビュー者の実際の開始日を入力する ※Teams専用チャネルにてメンバのステータスを確認 ※予定日を超えると赤色になります | AB8: SVレビュー者の実際の完了日を入力する ※Teams専用チャネルにてメンバのステータスを確認 ※予定日を超えると赤色になります | AC8: タスクの依頼元レビュー担当者を入力する ※必要に応じて記載 | AD8: タスクの依頼元レビュー完了日を入力する ※必要に応じて記載 | AE8: ー （マイタスクシートと連動・自動反映） | AG8: e
AG9: e
B10: 青字：関数で自動反映 | AG10: e
B11: 必須： | C11: ★ | D11: ★ | E11: ★ | F11: ★ | G11: ★ | H11: ★ | I11: ★ | J11: ★ | N11: 実行作業者 | S11: ピアレビュー担当者 | X11: SVレビュー担当者 | AC11: 依頼元レビュー担当者 | AG11: e
B12: # | C12: サービス管理番号 | D12: サービス名 | E12: 案件番号 | F12: 案件名 | G12: チーム(案件) | H12: 案件ステータス | I12: 案件デリバリ開始日 | J12: 案件デリバリ完了日 | K12: タスク番号 | L12: タスク名 | M12: タスクステータス | N12: 実行作業担当者 | O12: 予定：開始日 | P12: 予定：完了日 | Q12: 実績：開始日 | R12: 実績：完了日 | S12: ピアレビュー担当者 | T12: 予定：開始日 | U12: 予定：完了日 | V12: 実績：開始日 | W12: 実績：完了日 | X12: SVレビュー担当者 | Y12: 予定：開始日 | Z12: 予定：完了日 | AA12: 実績：開始日 | AB12: 実績：完了日 | AC12: 依頼元レビュー担当者 | AD12: 実績：依頼元レビュー完了日 | AE12: 自分の役割 | AF12: 採番用(触らない) | AG12: e
B13: 1 | C13: A0098 | D13: HR_myTIM/OTデータ作成(Google) | E13: A0098-0032 | F13: 【OT】HR_myTIM/OTデータ作成(Google) 12月度 | G13: 生麦X | H13: デリバリ完了 | I13: =$Q13 -> 0 | K13: A0098-0032-01 | L13: 【OT】HR_myTIM/OTデータ作成(Google) 12月度 調査依頼メール | M13: 集計完了 | N13: rintaro.watanabe | O13: 46000 | S13: shunsuke.taniguchi | T13: 46000 | X13: ryusei.inaba | Y13: 46000 | Z13: 46000 | AE13: =IF($N13=マイタスク!$U$5,"作業者","")&IF($S13=マイタスク!$U$5,"ピアレビュー","")&IF($X13=マイタスク!$U$5,"SVレビュー","") | AF13: =VALUE(RIGHT($E13,4)) -> 32 | AG13: e
B14: 2 | C14: A0098 | D14: HR_myTIM/OTデータ作成(Google) | E14: A0098-0032 | F14: 【OT】HR_myTIM/OTデータ作成(Google) 12月度 | G14: 生麦X | H14: デリバリ完了 | I14: =$Q14 -> 0 | K14: A0098-0032-02 | L14: 【OT】HR_myTIM/OTデータ作成(Google) 12月度 リマインド➀ | M14: 集計完了 | N14: rintaro.watanabe | O14: 46002 | S14: shunsuke.taniguchi | T14: 46002 | X14: ryusei.inaba | Y14: 46002 | Z14: 46002 | AE14: =IF($N14=マイタスク!$U$5,"作業者","")&IF($S14=マイタスク!$U$5,"ピアレビュー","")&IF($X14=マイタスク!$U$5,"SVレビュー","") | AF14: =VALUE(RIGHT($E14,4)) -> 32 | AG14: e
B15: 3 | C15: A0098 | D15: HR_myTIM/OTデータ作成(Google) | E15: A0098-0032 | F15: 【OT】HR_myTIM/OTデータ作成(Google) 12月度 | G15: 生麦X | H15: デリバリ完了 | I15: =$Q15 -> 0 | K15: A0098-0032-03 | L15: 【OT】HR_myTIM/OTデータ作成(Google) 12月度 リマインド② | M15: 集計完了 | N15: rintaro.watanabe | O15: 46003 | S15: shunsuke.taniguchi | T15: 46003 | X15: ryusei.inaba | Y15: 46003 | Z15: 46003 | AE15: =IF($N15=マイタスク!$U$5,"作業者","")&IF($S15=マイタスク!$U$5,"ピアレビュー","")&IF($X15=マイタスク!$U$5,"SVレビュー","") | AF15: =VALUE(RIGHT($E15,4)) -> 32 | AG15: e
B16: 4 | C16: A0098 | D16: HR_myTIM/OTデータ作成(Google) | E16: A0098-0032 | F16: 【OT】HR_myTIM/OTデータ作成(Google) 12月度 | G16: 生麦X | H16: デリバリ完了 | I16: =$Q16 -> 0 | K16: A0098-0032-04 | L16: 【OT】HR_myTIM/OTデータ作成(Google) 12月度 完了報告 | M16: 集計完了 | N16: rintaro.watanabe | O16: 46006 | S16: shunsuke.taniguchi | T16: 46006 | X16: ryusei.inaba | Y16: 46006 | Z16: 46006 | AE16: =IF($N16=マイタスク!$U$5,"作業者","")&IF($S16=マイタスク!$U$5,"ピアレビュー","")&IF($X16=マイタスク!$U$5,"SVレビュー","") | AF16: =VALUE(RIGHT($E16,4)) -> 32 | AG16: e
B17: 5 | C17: P1999 | D17: テスト運用サービス(SN) | E17: P1999-0073 | F17: 【テスト運用】HPS_JPiT月次基盤資料作成 | G17: 生麦X | H17: デリバリ完了 | I17: =$Q17 -> 0 | K17: P1999-0073-01 | L17: 【テスト運用】HPS_JPiT月次基盤資料作成 | M17: 集計完了 | N17: kazuma.motoyama | O17: 45356 | S17: kazuma.motoyama | T17: 45356 | X17: kazuma.motoyama | Y17: 45373 | Z17: 45373 | AE17: =IF($N17=マイタスク!$U$5,"作業者","")&IF($S17=マイタスク!$U$5,"ピアレビュー","")&IF($X17=マイタスク!$U$5,"SVレビュー","") | AF17: =VALUE(RIGHT($E17,4)) -> 73 | AG17: e
B18: 6 | C18: P3999 | D18: テスト運用サービス・データ計測不可(共通) | E18: P3999-1986 | F18: 【杉山さん】ツール練習 | G18: 生麦X | H18: デリバリ完了 | I18: =$Q18 -> 0 | K18: P3999-1986-01 | L18: 【杉山さん】ツール練習 | M18: 集計完了 | N18: joi.sugiyama | O18: 46149 | S18: manami.nanbu | T18: 46149 | X18: shingo.a.maeda | Y18: 46149 | Z18: 46149 | AE18: =IF($N18=マイタスク!$U$5,"作業者","")&IF($S18=マイタスク!$U$5,"ピアレビュー","")&IF($X18=マイタスク!$U$5,"SVレビュー","") | AF18: =VALUE(RIGHT($E18,4)) -> 1986 | AG18: e
B19: 7 | C19: A1031 | D19: I&D_Women's stories記事配信 | E19: A1031-0279 | F19: I&D_Women's stories記事配信 英訳追加① No1～7 | G19: 生麦X | H19: タスク進行中 | I19: =$Q19 -> 0 | K19: A1031-0279-01 | L19: I&D_Women's stories記事配信 英訳追加① No1～7 | M19: ピアレビュー | N19: riamu.daikusu | O19: 46153 | S19: rintaro.watanabe | T19: 46153 | X19: ryota.nozawa | Y19: 46185 | Z19: 46185 | AE19: =IF($N19=マイタスク!$U$5,"作業者","")&IF($S19=マイタスク!$U$5,"ピアレビュー","")&IF($X19=マイタスク!$U$5,"SVレビュー","") | AF19: =VALUE(RIGHT($E19,4)) -> 279 | AG19: e
B20: 8 | C20: A1031 | D20: I&D_Women's stories記事配信 | E20: A1031-0280 | F20: I&D_Women's stories記事配信 英訳追加② No8～13 | G20: 生麦X | H20: 内部完了 | I20: =$Q20 -> 0 | K20: A1031-0280-01 | L20: I&D_Women's stories記事配信 英訳追加② No8～13 | M20: 集計完了 | N20: rintaro.watanabe | O20: 46153 | S20: riamu.daikusu | T20: 46153 | X20: ryota.nozawa | Y20: 46185 | Z20: 46185 | AE20: =IF($N20=マイタスク!$U$5,"作業者","")&IF($S20=マイタスク!$U$5,"ピアレビュー","")&IF($X20=マイタスク!$U$5,"SVレビュー","") | AF20: =VALUE(RIGHT($E20,4)) -> 280 | AG20: e
B21: 9 | C21: P1999 | D21: テスト運用サービス(SN) | E21: P1999-0011 | F21: IC-Energy_石油3社のプレスリリース__日経News情報11/24週テスト運用① | G21: 生麦X | H21: デリバリ完了 | I21: =$Q21 -> 0 | K21: P1999-0011-01 | L21: IC-Energy_石油3社のプレスリリース__日経News情報11/24週テスト運用① | M21: 集計完了 | N21: ayumi.wada | O21: 44889.375 | S21: takuma.fukazawa | T21: 44889.375 | X21: takashi.muramatsu | Y21: 44889.375 | Z21: 44889.375 | AE21: =IF($N21=マイタスク!$U$5,"作業者","")&IF($S21=マイタスク!$U$5,"ピアレビュー","")&IF($X21=マイタスク!$U$5,"SVレビュー","") | AF21: =VALUE(RIGHT($E21,4)) -> 11 | AG21: e
B22: 10 | C22: A1025 | D22: 人事異動・組織改編情報チェック(自動化) | E22: A1025-0880 | F22: Nトレーニング人事異動（佐藤さん）⑦ | G22: 生麦X | H22: デリバリ完了 | I22: =$Q22 -> 0 | K22: A1025-0880-01 | L22: Nトレーニング人事異動（佐藤さん）⑦ | M22: 集計完了 | N22: takao.hattori | O22: 45974 | X22: takao.hattori | Y22: 45974 | Z22: 45974 | AE22: =IF($N22=マイタスク!$U$5,"作業者","")&IF($S22=マイタスク!$U$5,"ピアレビュー","")&IF($X22=マイタスク!$U$5,"SVレビュー","") | AF22: =VALUE(RIGHT($E22,4)) -> 880 | AG22: e
B23: 11 | C23: A1025 | D23: 人事異動・組織改編情報チェック(自動化) | E23: A1025-0881 | F23: Nトレーニング人事異動（佐藤さん）⑦ | G23: 生麦X | H23: デリバリ完了 | I23: =$Q23 -> 0 | K23: A1025-0881-01 | L23: Nトレーニング人事異動（佐藤さん）⑦ | M23: 集計完了 | N23: yuya.tanigaki | O23: 45974 | S23: yuya.tanigaki | T23: 45974 | Z23: 45974 | AE23: =IF($N23=マイタスク!$U$5,"作業者","")&IF($S23=マイタスク!$U$5,"ピアレビュー","")&IF($X23=マイタスク!$U$5,"SVレビュー","") | AF23: =VALUE(RIGHT($E23,4)) -> 881 | AG23: e
B24: 12 | C24: P3999 | D24: テスト運用サービス・データ計測不可(共通) | E24: P3999-1701 | F24: Nトレーニング人事異動（佐藤さん）⑦ | G24: 生麦X | H24: デリバリ完了 | I24: =$Q24 -> 0 | K24: P3999-1701-01 | L24: Nトレーニング人事異動（佐藤さん）⑦ | M24: 集計完了 | N24: yuya.tanigaki | O24: 45974 | S24: yuya.tanigaki | T24: 45974 | Z24: 45975 | AE24: =IF($N24=マイタスク!$U$5,"作業者","")&IF($S24=マイタスク!$U$5,"ピアレビュー","")&IF($X24=マイタスク!$U$5,"SVレビュー","") | AF24: =VALUE(RIGHT($E24,4)) -> 1701 | AG24: e
B25: 13 | C25: P3999 | D25: テスト運用サービス・データ計測不可(共通) | E25: P3999-1705 | F25: Nトレーニング人事異動（佐藤さん）⑦ | G25: 生麦X | H25: デリバリ完了 | I25: =$Q25 -> 0 | K25: P3999-1705-01 | L25: Nトレーニング人事異動（佐藤さん）⑦ | M25: 集計完了 | N25: yuya.tanigaki | O25: 45974 | S25: yuya.tanigaki | T25: 45974 | Z25: 45974 | AE25: =IF($N25=マイタスク!$U$5,"作業者","")&IF($S25=マイタスク!$U$5,"ピアレビュー","")&IF($X25=マイタスク!$U$5,"SVレビュー","") | AF25: =VALUE(RIGHT($E25,4)) -> 1705 | AG25: e
B26: 14 | C26: P3999 | D26: テスト運用サービス・データ計測不可(共通) | E26: P3999-1702 | F26: Nトレーニング人事異動（山岸さん）⑦ | G26: 生麦X | H26: デリバリ完了 | I26: =$Q26 -> 0 | K26: P3999-1702-01 | L26: Nトレーニング人事異動（山岸さん）⑦ | M26: 集計完了 | N26: yuya.tanigaki | O26: 45974 | S26: yuya.tanigaki | T26: 45974 | Z26: 45975 | AE26: =IF($N26=マイタスク!$U$5,"作業者","")&IF($S26=マイタスク!$U$5,"ピアレビュー","")&IF($X26=マイタスク!$U$5,"SVレビュー","") | AF26: =VALUE(RIGHT($E26,4)) -> 1702 | AG26: e
B27: 15 | C27: P3999 | D27: テスト運用サービス・データ計測不可(共通) | E27: P3999-1704 | F27: Nトレーニング人事異動（山岸さん）⑦ | G27: 生麦X | H27: デリバリ完了 | I27: =$Q27 -> 0 | K27: P3999-1704-01 | L27: Nトレーニング人事異動（山岸さん）⑦ | M27: 集計完了 | N27: yuya.tanigaki | O27: 45974 | S27: yuya.tanigaki | T27: 45974 | Z27: 45974 | AE27: =IF($N27=マイタスク!$U$5,"作業者","")&IF($S27=マイタスク!$U$5,"ピアレビュー","")&IF($X27=マイタスク!$U$5,"SVレビュー","") | AF27: =VALUE(RIGHT($E27,4)) -> 1704 | AG27: e
B28: 16 | C28: A1072 | D28: Technology_アクセンチュア健保_chatbot運用保守 | E28: A1072-0036 | F28: Technology_アクセンチュア健保_chatbot運用保守2/3・6 | G28: 生麦X | H28: デリバリ完了 | I28: =$Q28 -> 0 | K28: A1072-0036-01 | L28: Technology_アクセンチュア健保_chatbot運用保守2/3・6 | M28: 集計完了 | N28: takuma.fukazawa | O28: 44960.375 | S28: ryota.nozawa | T28: 44963.375 | X28: ryota.nozawa | Y28: 44963.375 | Z28: 44963.375 | AE28: =IF($N28=マイタスク!$U$5,"作業者","")&IF($S28=マイタスク!$U$5,"ピアレビュー","")&IF($X28=マイタスク!$U$5,"SVレビュー","") | AF28: =VALUE(RIGHT($E28,4)) -> 36 | AG28: e
B29: 17 | C29: A1025 | D29: 人事異動・組織改編情報チェック(自動化) | E29: A1025-0409 | F29: (追加)(PRD_人事異動・組織改編情報チェック(日経転記)⑥(3/4週) | G29: 生麦X | H29: デリバリ完了 | I29: =$Q29 -> 0 | K29: A1025-0409-01 | L29: (追加)(PRD_人事異動・組織改編情報チェック(日経転記)⑥(3/4週) | M29: 集計完了 | N29: kazuma.motoyama | O29: 45355 | S29: ayumi.wada | T29: 45359 | X29: kazuma.motoyama | Y29: 45359 | Z29: 45359 | AE29: =IF($N29=マイタスク!$U$5,"作業者","")&IF($S29=マイタスク!$U$5,"ピアレビュー","")&IF($X29=マイタスク!$U$5,"SVレビュー","") | AF29: =VALUE(RIGHT($E29,4)) -> 409 | AG29: e
B30: 18 | C30: A1025 | D30: 人事異動・組織改編情報チェック(自動化) | E30: A1025-0408 | F30: (追加)PRD_人事異動・組織改編情報チェック(日経転記)⑤(3/4週) | G30: 生麦X | H30: デリバリ完了 | I30: =$Q30 -> 0 | K30: A1025-0408-01 | L30: (追加)PRD_人事異動・組織改編情報チェック(日経転記)⑤(3/4週) | M30: 集計完了 | N30: ayumi.wada | O30: 45355 | S30: kazuma.motoyama | T30: 45359 | X30: kazuma.motoyama | Y30: 45359 | Z30: 45359 | AE30: =IF($N30=マイタスク!$U$5,"作業者","")&IF($S30=マイタスク!$U$5,"ピアレビュー","")&IF($X30=マイタスク!$U$5,"SVレビュー","") | AF30: =VALUE(RIGHT($E30,4)) -> 408 | AG30: e
B31: 19 | C31: P1000 | D31: 共通(SN) | E31: P1000-0130 | F31: [A1024]Digital_マイナポWeb問合せ回答_マニュアル修正 | G31: 生麦X | H31: デリバリ完了 | I31: =$Q31 -> 0 | K31: P1000-0130-01 | L31: [A1024]Digital_マイナポWeb問合せ回答_マニュアル修正 | M31: 集計完了 | N31: yuichi.kimura | O31: 44950.375 | S31: ryota.nozawa | T31: 44953.375 | X31: shigeki.ohtake | Y31: 44953.375 | Z31: 44953.375 | AE31: =IF($N31=マイタスク!$U$5,"作業者","")&IF($S31=マイタスク!$U$5,"ピアレビュー","")&IF($X31=マイタスク!$U$5,"SVレビュー","") | AF31: =VALUE(RIGHT($E31,4)) -> 130 | AG31: e
B32: 20 | C32: P1000 | D32: 共通(SN) | E32: P1000-0137 | F32: [A1046]CMT_クライアントのメディアリリース情報確認_マニュアル修正 | G32: 生麦X | H32: デリバリ完了 | I32: =$Q32 -> 0 | K32: P1000-0137-01 | L32: [A1046]CMT_クライアントのメディアリリース情報確認_マニュアル修正 | M32: 集計完了 | N32: yumi.terui | O32: 44970.375 | S32: takuma.fukazawa | T32: 44970.375 | X32: ayumi.wada | Y32: 44985.375 | Z32: 44985.375 | AE32: =IF($N32=マイタスク!$U$5,"作業者","")&IF($S32=マイタスク!$U$5,"ピアレビュー","")&IF($X32=マイタスク!$U$5,"SVレビュー","") | AF32: =VALUE(RIGHT($E32,4)) -> 137 | AG32: e
B33: 21 | C33: P3999 | D33: テスト運用サービス・データ計測不可(共通) | E33: P3999-1523 | F33: _HR_安全衛生委員会データ作成【横田さん】 | G33: 生麦X | H33: デリバリ完了 | I33: =$Q33 -> 0 | K33: P3999-1523-01 | L33: HR_安全衛生委員会データ作成【横田さん】 | M33: 集計完了 | N33: shinji.yokota | O33: 45861 | X33: shingo.a.maeda | Y33: 45861 | Z33: 45861 | AE33: =IF($N33=マイタスク!$U$5,"作業者","")&IF($S33=マイタスク!$U$5,"ピアレビュー","")&IF($X33=マイタスク!$U$5,"SVレビュー","") | AF33: =VALUE(RIGHT($E33,4)) -> 1523 | AG33: e
B34: 22 | C34: P3999 | D34: テスト運用サービス・データ計測不可(共通) | E34: P3999-1742 | F34: 【〆野さん】NトレーニングSupplier | G34: 生麦X | H34: デリバリ完了 | I34: =$Q34 -> 0 | K34: P3999-1742-01 | L34: 【〆野さん】NトレーニングSupplier ① | M34: 集計完了 | N34: kasumi.shimeno | O34: 46000 | S34: takao.hattori | T34: 46000 | X34: keita.anzai | Y34: 46000 | Z34: 46014 | AE34: =IF($N34=マイタスク!$U$5,"作業者","")&IF($S34=マイタスク!$U$5,"ピアレビュー","")&IF($X34=マイタスク!$U$5,"SVレビュー","") | AF34: =VALUE(RIGHT($E34,4)) -> 1742 | AG34: e
B35: 23 | C35: P3999 | D35: テスト運用サービス・データ計測不可(共通) | E35: P3999-1742 | F35: 【〆野さん】NトレーニングSupplier | G35: 生麦X | H35: デリバリ完了 | I35: =$Q35 -> 0 | K35: P3999-1742-02 | L35: 【〆野さん】NトレーニングSupplier ② | M35: 集計完了 | N35: kasumi.shimeno | O35: 46001 | S35: minoru.fujita | T35: 46001 | X35: keita.anzai | Y35: 46001 | Z35: 46001 | AE35: =IF($N35=マイタスク!$U$5,"作業者","")&IF($S35=マイタスク!$U$5,"ピアレビュー","")&IF($X35=マイタスク!$U$5,"SVレビュー","") | AF35: =VALUE(RIGHT($E35,4)) -> 1742 | AG35: e
B36: 24 | C36: P3999 | D36: テスト運用サービス・データ計測不可(共通) | E36: P3999-1742 | F36: 【〆野さん】NトレーニングSupplier | G36: 生麦X | H36: デリバリ完了 | I36: =$Q36 -> 0 | K36: P3999-1742-03 | L36: 【〆野さん】NトレーニングSupplier ③ | M36: 集計完了 | N36: kasumi.shimeno | O36: 46003 | S36: minoru.fujita | T36: 46003 | X36: keita.anzai | Y36: 46003 | Z36: 46017 | AE36: =IF($N36=マイタスク!$U$5,"作業者","")&IF($S36=マイタスク!$U$5,"ピアレビュー","")&IF($X36=マイタスク!$U$5,"SVレビュー","") | AF36: =VALUE(RIGHT($E36,4)) -> 1742 | AG36: e
B37: 25 | C37: P3999 | D37: テスト運用サービス・データ計測不可(共通) | E37: P3999-1757 | F37: 【〆野さん】サーバールームTRG | G37: 生麦X | H37: デリバリ完了 | I37: =$Q37 -> 0 | K37: P3999-1757-01 | L37: 【〆野さん】サーバールームTRG(7月分)【Excel工程】 | M37: 集計完了 | N37: kasumi.shimeno | O37: 46010 | S37: shinra.sakaki | T37: 46010 | X37: takao.hattori | Y37: 46010 | Z37: 46010 | AE37: =IF($N37=マイタスク!$U$5,"作業者","")&IF($S37=マイタスク!$U$5,"ピアレビュー","")&IF($X37=マイタスク!$U$5,"SVレビュー","") | AF37: =VALUE(RIGHT($E37,4)) -> 1757 | AG37: e
B38: 26 | C38: P3999 | D38: テスト運用サービス・データ計測不可(共通) | E38: P3999-1757 | F38: 【〆野さん】サーバールームTRG | G38: 生麦X | H38: デリバリ完了 | I38: =$Q38 -> 0 | K38: P3999-1757-02 | L38: 【〆野さん】サーバールームTRG(7月分)【メール工程】 | M38: 集計完了 | N38: kasumi.shimeno | O38: 46010 | S38: shinra.sakaki | T38: 46010 | X38: takao.hattori | Y38: 46010 | Z38: 46010 | AE38: =IF($N38=マイタスク!$U$5,"作業者","")&IF($S38=マイタスク!$U$5,"ピアレビュー","")&IF($X38=マイタスク!$U$5,"SVレビュー","") | AF38: =VALUE(RIGHT($E38,4)) -> 1757 | AG38: e
B39: 27 | C39: P3999 | D39: テスト運用サービス・データ計測不可(共通) | E39: P3999-1766 | F39: 【〆野さん】サーバールームTRG 8月分 | G39: 生麦X | H39: デリバリ完了 | I39: =$Q39 -> 0 | K39: P3999-1766-01 | L39: 【〆野さん】サーバールームTRG 8月分 Excel作成工程 | M39: 集計完了 | N39: kasumi.shimeno | O39: 46013 | S39: shinra.sakaki | T39: 46013 | X39: takao.hattori | Y39: 46013 | Z39: 46017 | AE39: =IF($N39=マイタスク!$U$5,"作業者","")&IF($S39=マイタスク!$U$5,"ピアレビュー","")&IF($X39=マイタスク!$U$5,"SVレビュー","") | AF39: =VALUE(RIGHT($E39,4)) -> 1766 | AG39: e
B40: 28 | C40: P3999 | D40: テスト運用サービス・データ計測不可(共通) | E40: P3999-1766 | F40: 【〆野さん】サーバールームTRG 8月分 | G40: 生麦X | H40: デリバリ完了 | I40: =$Q40 -> 0 | K40: P3999-1766-02 | L40: 【〆野さん】サーバールームTRG 8月分 メール作成工程 | M40: 集計完了 | N40: kasumi.shimeno | O40: 46013 | S40: shinra.sakaki | T40: 46013 | X40: takao.hattori | Y40: 46013 | Z40: 46017 | AE40: =IF($N40=マイタスク!$U$5,"作業者","")&IF($S40=マイタスク!$U$5,"ピアレビュー","")&IF($X40=マイタスク!$U$5,"SVレビュー","") | AF40: =VALUE(RIGHT($E40,4)) -> 1766 | AG40: e
...

Sheet マイタスク
B1: ***Highly Confidential. Not To Be Distributed Further Without Authorization of the Sender. *** Copyright © 2026 Accenture. All rights reserved.
B2: PJT・サテライトのみ共有可
AF3: e
K4: マイタスクシート | AF4: e
R5: 自分のEIDを入力→ | U5: EIDxxxxx | AF5: e
AF6: e
N7: 実行作業者 | S7: ピアレビュー担当者 | X7: SVレビュー担当者 | AC7: 依頼元レビュー担当者 | AF7: e
B8: # | C8: サービス管理番号 | D8: サービス名 | E8: 案件番号 | F8: 案件名 | G8: チーム(案件) | H8: 案件ステータス | I8: 案件デリバリ開始日 | J8: 案件デリバリ完了日 | K8: タスク番号 | L8: タスク名 | M8: タスクステータス | N8: 実行作業担当者 | O8: 予定：開始日 | P8: 予定：完了日 | Q8: 実績：開始日 | R8: 実績：完了日 | S8: ピアレビュー担当者 | T8: 予定：開始日 | U8: 予定：完了日 | V8: 実績：開始日 | W8: 実績：完了日 | X8: SVレビュー担当者 | Y8: 予定：開始日 | Z8: 予定：完了日 | AA8: 実績：開始日 | AB8: 実績：完了日 | AC8: 依頼元レビュー担当者 | AD8: 実績：依頼元レビュー完了日 | AE8: 自分の役割 | AF8: e
B9: {=IFERROR(_xlfn._xlws.FILTER(案件管理マスタ_案件・タスク版!$B$13:$AE$1048576,(TRIM(案件管理マスタ_案件・タスク版!$N$13:$N$1048576)=TRIM($U$5))+(TRIM(案件管理マスタ_案件・タスク版!$S$13:$S$1048576)=TRIM($U$5))+(TRIM(案件管理マスタ_案件・タスク版!$X$13:$X$1048576)=TRIM($U$5)),"該当タスクなし"),"該当タスクなし")} -> 該当タスクなし | AF9: e
AF10: e
AF11: e
AF12: e
AF13: e
AF14: e
AF15: e
AF16: e
AF17: e
AF18: e
AF19: e
AF20: e
AF21: e
... AF569: e
A570: e | B570: e | C570: e | D570: e | E570: e | F570: e | G570: e | H570: e | I570: e | J570: e | K570: e | L570: e | M570: e | N570: e | O570: e | P570: e | Q570: e | R570: e | S570: e | T570: e | U570: e | V570: e | W570: e | X570: e | Y570: e | Z570: e | AA570: e | AB570: e | AC570: e | AD570: e | AE570: e | AF570: e

Sheet マスタ-->

Sheet サービス情報マスタcopy
B1: 凡例 | AN1: ↓↓↓ | BB1: e
B2: フリーテキストエリア | F2: 別チームへのサービス移管を行う場合、移管元/移管先の拠点に依存せず、常に新規サービス番号を採番する。 | BB2: e
B3: 値選択エリア | BB3: e
B4: 自動表示(関数)エリア | F4: ↓PJT運用企画Tで決定・記入 | L4: › | AG4: ↓G列に共通している名称をAG列に記入 | AI4: ↓PJT業務企画Tで記入 | AO4: ↓サテライト(SSD/担当T)、PJTで記入 | AQ4: ↓PJT運用企画Tで記入【2025/05廃止予定】 | AT4: ↓PJT運用企画Tで記入 | AU4: 最新更新日➡ | AV4: =MAX(AV8:AV431) -> 45902 | BB4: e
B5: ★受託ｻｰﾋﾞｽ： WDM登録項目 | D5: ★ | E5: ★WDM登録項目 | F5: ★ | G5: ★ | H5: ★ | I5: ★ | J5: ★ | K5: ★ | Z5: ★ | AA5: ★ | AC5: ★（サービス停止時に記入） | AI5: ★ | AJ5: ★ | AK5: ★ | AL5: ★ | BB5: e
A6: =IF(Z6="サービス停止",Z6,"") | B6: サービス管理番号 | C6: サービス管理番号 重複チェック | D6: 案件種別 | E6: 旧サービス 管理番号 | F6: サービスカテゴリ | G6: サービス名 | H6: サービス概要 | I6: 担当拠点 | J6: 担当チーム | K6: 担当SV | L6: 配送物 の有無 | M6: 頻度 | N6: 依頼方法 | O6: 納期 (リードタイム) | P6: 依頼者からの レビューバック | Q6: 成果物の 提出方法 | R6: データ保持期限 | S6: 依頼者への完了報告 | U6: 対応リスク | V6: 依頼元への権限付与依頼 | W6: 依頼元 | Z6: ステータス | AA6: サービス開始年月日 | AC6: サービス停止年月日 | AE6: 移管先サービス番号 | AF6: 単発依頼フラグ | AG6: サービスグループ情報 | AI6: 組織情報(集計用) | AN6: メモ/備考 | AO6: WDMメンテステータス | AQ6: 運用企画T | AY6: 運用企画T_必須入力項目確認 | BA6: 記載順ソート用No | BB6: e
S7: 返信方法 | T7: 返信手段 | U7: 扱っているデータに顧客データ/情報が含まれている | W7: DTE | X7: 担当者 | Y7: スポンサーMD | AA7: システム有効開始 | AB7: 業務的開始日 | AC7: システム有効終了 | AD7: 業務的停止日 | AG7: グループ | AH7: 順序 | AI7: ①組織名 | AJ7: ①割合 | AK7: ②組織名 | AL7: ②割合 | AM7: 更新日 | AO7: Status | AP7: 備考 | AQ7: 【2025/05廃止予定】 データ計測方法検討ステータス | AR7: 【2025/05廃止予定】 ステータス更新日 | AS7: 【作業後廃止予定】 WDM登録状況 (2025/5/8時点) | AT7: WDM登録方針(2025/5/8以降) | AU7: 備考 | AV7: 方針決定日 | AW7: 対応内容 (Liさんへの依頼) | AX7: 対応日 (担当:Liさん) | AY7: 必須入力 Check <サテライト> | AZ7: 必須入力Check <PJT> | BB7: e
A8: =IF(Z8="サービス停止",Z8,"") -> サービス停止 | C8: =IF(B8="","-",IF(COUNTIF($B$8:B8,B8)=1,"〇","×")) -> - | D8: 受託 | E8: SN_0001 | F8: 07入力・登録代行 | G8: 名刺情報入力代行 | H8: Outlookの連絡先に連絡先を追加するマクロの入力テンプレート(myBiC)に名刺情報を入力する。 | I8: 生麦 | K8: emiko.maeyama | L8: 有 | M8: 随時 | N8: リクエストフォーム | O8: 入力：4営業日 ※Outbox投函からmyBiC提供まで最長1ヶ月 | P8: 無 (但し、入力不備があった場合はメールでの指摘有り) | Q8: SharePoint上の個別フォルダ (権限設定有り) | R8: SharePoint上は3か月 | S8: 手動 | T8: ・アップロード完了連絡 ・配送完了連絡 | U8: 〇 | V8: × | W8: Strategy | X8: 別紙参照（SN_対象者リスト_20200529_v1.0） | Z8: サービス停止 | AA8: 43709 | AB8: ー | AC8: FY24以前 | AD8: ー | AI8: ー | AJ8: ー | AK8: ー | AL8: ー | AN8: myTE経費入力代行と同時依頼 2019/11/1より、リクエストフォームからの非定常サービスに変更 但し、名刺返却はmyTE経費入力代行と同タイミングで配送 ・2022年7月より、立川Ｘチームにサービス移管（ST_0049） | AO8: - | AS8: (サービス停止) | AT8: 9.対応不要 | AV8: 45785 | AY8: =IF(D8="受託",IF(COUNTA(B8,F8,G8:J8,Z8:AA8)=8,"OK","NG"),"確認対象外") -> NG | AZ8: =ISNUMBER(AJ8) -> FALSE | BA8: =ROW()-7 -> 1 | BB8: e
A9: =IF(Z9="サービス停止",Z9,"") -> サービス停止 | C9: =IF(B9="","-",IF(COUNTIF($B$8:B9,B9)=1,"〇","×")) -> - | D9: 受託 | E9: SN_0002 | G9: myTE経費入力代行 | H9: myTEの入力補助マクロ(myTES)の 入力テンプレートに経費情報を入力する。 | I9: 生麦 | K9: emiko.maeyama | L9: 有 | M9: 指定Period | N9: 定常作業のため、無し (情報提供依頼メールへの返信によって、対応開始) | O9: 入力：4営業日 | P9: 無 (但し、入力不備があった場合はメールでの指摘有り) | Q9: SharePoint上の個別フォルダ (権限設定有り) | R9: SharePoint上は3か月 | S9: 手動 | T9: ・アップロード完了連絡 ・配送完了連絡 | U9: 〇 | V9: × | W9: Strategy | X9: 別紙参照（SN_対象者リスト_20200529_v1.0） | Z9: サービス停止 | AA9: 43709 | AB9: ー | AC9: FY24以前 | AD9: ー | AI9: ー | AJ9: ー | AK9: ー | AL9: ー | AN9: 名刺情報入力代行と同時依頼 2019/11/15Pより、各依頼者に対し、全Period分を対応。(1Periodは、2グループに分けて実施) ・2022/6/30Pをもって、サービス終了 | AO9: - | AS9: (サービス停止) | AT9: 9.対応不要 | AV9: 45785 | AY9: =IF(D9="受託",IF(COUNTA(B9,F9,G9:J9,Z9:AA9)=8,"OK","NG"),"確認対象外") -> NG | AZ9: =ISNUMBER(AJ9) -> FALSE | BA9: =ROW()-7 -> 2 | BB9: e
A10: =IF(Z10="サービス停止",Z10,"") | B10: A1003 | C10: =IF(B10="","-",IF(COUNTIF($B$8:B10,B10)=1,"〇","×")) -> 〇 | D10: 受託 | E10: SN_0003 | F10: 03サニタイズ編集 | G10: KXサニタイズ代行 | H10: 依頼されたドキュメントをKXに登録可能なフォーマットに修正する。 2020/10/1以降から、SN_0027の後続タスク追加 Quarter単位でサニタイズ依頼が発生(Best project、FORM) フローから外れたもののみ、リクエストフォームでの依頼 | I10: 生麦 | J10: TF | K10: tomoyuki.a.hishiki | L10: 無 | M10: 随時 | N10: ・SN内担当チームからのメール受信 ・リクエストフォーム | O10: 一次提出：3週間 納期:4週間 | P10: 有(メール) レビューバック反映も実施する | Q10: SharePoint上の個別フォルダ (権限設定有り) | R10: 作業完了後3ヶ月経過したら削除 | S10: 手動 | T10: ・アップロード完了連絡 | U10: 〇 | V10: × | W10: CF_KM | X10: 酒井さん（takahiro.a.sakai）:BEST担当 西田さん（kumiko.nishida）:BEST担当 榊原さん（anna.sakakibara）:FORM担当 Japan.ACSKM@accenture.com Japan.ACSKM.FORM@accenture.com | Z10: =IF(AC10="",IF(AA10="","",IF(TODAY()>=AA10,"サービス開始",IF(TODAY()<AA10,"本稼働前",""))),IF(TODAY()>=AC10,"サービス停止",IF(AA10="","",IF(TODAY()>=AA10,"サービス開始",IF(TODAY()<AA10,"本稼働前",""))))) -> サービス開始 | AA10: 43770 | AB10: ー | AG10: KXサニタイズ代行 | AH10: ①A1004 ②A1003 | AI10: Corporate Function | AJ10: 1 | AK10: ー | AL10: ー | AM10: 45674 | AN10: 2021/10/1より、担当SV変更：Maeyama→（Takahashi,Airi)→Ito 2022/05/15より、担当SV変更：Ito→Watanabe 2023/3/1より、担当SV変更：koji.c.watanabe→hiroyuki.hishiki | AO10: - | AQ10: A_通常_決定(登録可) | AS10: 登録済_本登録 | AT10: 4b.本登録_計測方法確定(FY24以前) | AV10: 45785 | AY10: =IF(D10="受託",IF(COUNTA(B10,F10,G10:J10,Z10:AA10)=8,"OK","NG"),"確認対象外") -> OK | AZ10: =ISNUMBER(AJ10) -> TRUE | BA10: =ROW()-7 -> 3 | BB10: e
A11: =IF(Z11="サービス停止",Z11,"") | B11: A1004 | C11: =IF(B11="","-",IF(COUNTIF($B$8:B11,B11)=1,"〇","×")) -> 〇 | D11: 受託 | E11: SN_0004 | F11: 02サニタイズ編集要件 | G11: WordList作成作業(KXサニタイズ代行) | H11: KXサニタイズに必要なWordListを作成する。 2020/10/1以降から、SN_0027の後続タスク追加 Quarter単位でサニタイズ依頼が発生(Best project、FORM) フローから外れたもののみ、リクエストフォームでの依頼 | I11: 生麦 | J11: TF | K11: tomoyuki.a.hishiki | L11: 無 | M11: 随時 | N11: ・SN内担当チームからのメール受信 ・リクエストフォーム | O11: 一次提出：3週間 納期:4週間 | P11: 有(メール) レビューバック反映も実施する | Q11: SharePoint上の個別フォルダ (権限設定有り) | R11: 作業完了後3ヶ月経過したら削除 | S11: 手動 | T11: ・アップロード完了連絡 | U11: 〇 | V11: × | W11: CF_KM | X11: 酒井さん（takahiro.a.sakai）:BEST担当 西田さん（kumiko.nishida）:BEST担当 榊原さん（anna.sakakibara）:FORM担当 Japan.ACSKM@accenture.com Japan.ACSKM.FORM@accenture.com | Z11: =IF(AC11="",IF(AA11="","",IF(TODAY()>=AA11,"サービス開始",IF(TODAY()<AA11,"本稼働前",""))),IF(TODAY()>=AC11,"サービス停止",IF(AA11="","",IF(TODAY()>=AA11,"サービス開始",IF(TODAY()<AA11,"本稼働前",""))))) -> サービス開始 | AA11: 43770 | AB11: ー | AG11: KXサニタイズ代行 | AH11: ①A1004 ②A1003 | AI11: Corporate Function | AJ11: 1 | AK11: ー | AL11: ー | AM11: 45674 | AN11: 2019/11/1より、案件リスト上で分割。 KXサニタイズ作業とWordlist作成が同時に依頼された場合、別の案件として起票する。 2021/10/1より、担当SV変更：Maeyama→（Takahashi,Airi)→Ito 2022/05/15より、担当SV変更：Ito→Watanabe 2023/3/1より、担当SV変更：koji.c.watanabe→hiroyuki.hishiki | AO11: - | AQ11: A_通常_決定(登録可) | AS11: 登録済_本登録 | AT11: 4b.本登録_計測方法確定(FY24以前) | AV11: 45785 | AY11: =IF(D11="受託",IF(COUNTA(B11,F11,G11:J11,Z11:AA11)=8,"OK","NG"),"確認対象外") -> OK | AZ11: =ISNUMBER(AJ11) -> TRUE | BA11: =ROW()-7 -> 4 | BB11: e
A12: =IF(Z12="サービス停止",Z12,"") -> サービス停止 | C12: =IF(B12="","-",IF(COUNTIF($B$8:B12,B12)=1,"〇","×")) -> - | D12: 受託 | E12: SN_0005 | G12: MCOM_記事配信(中途社員紹介) | H12: MCOMの配信用記事の中途社員紹介を作成する。 | I12: 生麦 | K12: akiko.a.hirano | L12: 無 | M12: 月次 | N12: 定常作業のため、無し (指定のフォルダーに毎月15日17:00までに格納(15日が土日祝日の場合、その前の営業日)され次営業日より、対応開始) | O12: 作成：3営業日 | P12: 無 (メールにてレビューバックはあるが、指摘反映は不要) | Q12: レビューURLをメールにて送付 | S12: 手動 | T12: 作業提出メールと同時に完了報告を行う | U12: 〇 | V12: 〇 Wordpress （指定の申請書に直接記入で申請メールなし：備考欄参照） | W12: CF_MCOM | X12: 河村さん（takuro.kawamura） →魚住さん(Uozumi, Azusa) 加藤さん（mayako.kato）退職 小畑さん（kaoru.obata）退職 IMJ担当者 村上さん（kumiko.murakami) | Z12: サービス停止 | AA12: 43770 | AB12: ー | AC12: FY24以前 | AD12: ー | AI12: ー | AJ12: ー | AK12: ー | AL12: ー | AM12: 45674 | AN12: 2019年11月より開始で、初回は2019/11/15に作業依頼として依頼元が、指定フォルダーに格納 ■Japan information siteの「Editor」権限が必要。 下記申請フォームに入力。(いむじぇ分の登録も必要) https://ts.accenture.com/:x:/r/Sites/mcomjapan/_layouts/15/Doc.aspx?sourcedoc=%7B97EFB4A5-D615-4C87-B04E-09AAA524F65B%7D&file=ApplicationForm-EditingRightsForJIS_2020.xlsx&action=default&mobileredirect=true&cid=f148a7a4-b329-46fa-a3b0-6c1cb44c4d8b ※いむじぇ追加の場合IMJ側の担当者の情報もメモ欄に記入が必要。 2021/12/20 依頼元からの作業依頼が滞っていたため、状況を確認。中途社員紹介はIMJの案件だったが、先日完全子会社となったこともあり諸々体制が変更中のため、一旦クローズして構わない。→クローズ。 | AO12: - | AS12: (サービス停止) | AT12: 9.対応不要 | AV12: 45785 | AY12: =IF(D12="受託",IF(COUNTA(B12,F12,G12:J12,Z12:AA12)=8,"OK","NG"),"確認対象外") -> NG | AZ12: =ISNUMBER(AJ12) -> FALSE | BA12: =ROW()-7 -> 5 | BB12: e
A13: =IF(Z13="サービス停止",Z13,"") | B13: A1006 | C13: =IF(B13="","-",IF(COUNTIF($B$8:B13,B13)=1,"〇","×")) -> 〇 | D13: 受託 | E13: SN_0006 | F13: 05配信記事編集 | G13: MCOM_記事配信(Article)-Media Report | H13: MCOMの配信用記事のArticleのMedia Reportを作成する。 | I13: 生麦 | J13: 生麦Z | K13: =IFERROR(VLOOKUP([9]サービス一覧!J13,[9]List!$M$3:$N$24,2,FALSE)&"","") -> hiroyuki.yoshida | L13: 無 | M13: 週次 | N13: メールで日本語と英語の記事が届く。定常作業のため、無し (指定のフォルダーに毎週月曜17:00 毎週火曜日18:00 までに格納された分を翌営業日から対応開始) | O13: 記事作成対象期間の最終日の1営業日後から3営業日目まで | P13: 無(Teamsにてレビューバックはあるが、指摘反映は不要) | Q13: Formsに記事のURL等を記入して提出 | R13: １カ月 | S13: 手動 | T13: Teams | U13: × | V13: 〇 Wordpress （指定の申請書に直接記入で申請メールなし：備考欄参照） | W13: CF_MCOM | X13: 魚住さん（azusa.uozumi） 村上さん（ayami.murakami） | Z13: =IF(AC13="",IF(AA13="","",IF(TODAY()>=AA13,"サービス開始",IF(TODAY()<AA13,"本稼働前",""))),IF(TODAY()>=AC13,"サービス停止",IF(AA13="","",IF(TODAY()>=AA13,"サービス開始",IF(TODAY()<AA13,"本稼働前",""))))) -> サービス開始 | AA13: 43770 | AB13: ー | AI13: Corporate Function | AJ13: 1 | AK13: ー | AL13: ー | AM13: 45674 | AN13: 2019年11月より開始で、初回は2019/11/5に作業依頼として依頼元が、指定フォルダーに格納 2020年6月9日より、格納タイミングを変更 ■Japan information siteの「Editor」権限が必要。 下記申請フォームに入力。 https://ts.accenture.com/:x:/r/Sites/mcomjapan/_layouts/15/Doc.aspx?sourcedoc=%7B97EFB4A5-D615-4C87-B04E-09AAA524F65B%7D&file=ApplicationForm-EditingRightsForJIS_2020.xlsx&action=default&mobileredirect=true&cid=f148a7a4-b329-46fa-a3b0-6c1cb44c4d8b 2026/3/1：担当SV変更（hiroshi.a.harashima → hiroyuki.yoshida） | AO13: - | AQ13: A_通常_決定(登録可) | AS13: 登録済_本登録 | AT13: 3.登録修正_計測方法要再検討 | AU13: ＜10/7＞ 変更業務確認し、サービスカテゴリ「05配信記事編集」と再定義 ＜5/8＞ 定義済み計測方法ではなくなった為(担当チームで独自に変更)、サービスカテゴリ「05配信記事編集」から「93TBD_保留」へ変更 ➡WDM登録方法： ・サービスカテゴリ変更は、新規登録(別レコード)で行う。 ・旧サービスカテゴリ「05配信記事編集」のサービスの停止日は、2025/06/08とする。 | AV13: 45785 | AW13: ('25/10/7)サービスカテゴリを変更 | AX13: 45786 | AY13: =IF(D13="受託",IF(COUNTA(B13,F13,G13:J13,Z13:AA13)=8,"OK","NG"),"確認対象外") -> OK | AZ13: =ISNUMBER(AJ13) -> TRUE | BA13: =ROW()-7 -> 6 | BB13: e
A14: =IF(Z14="サービス停止",Z14,"") -> サービス停止 | B14: A1007 | C14: =IF(B14="","-",IF(COUNTIF($B$8:B14,B14)=1,"〇","×")) -> 〇 | D14: 受託 | E14: SN_0007 | F14: 08データ集計・整形 | G14: WP_社内環境データ集計(Census) | H14: WPの社内環境データ集計として、Censusを集計する。(対象ビル：３) | I14: 生麦 | J14: 生麦Y | K14: emiko.maeyama | L14: 無 | M14: 週次 | N14: 定常作業のため、無し (指定のフォルダーに毎週金曜17:00までに格納) | O14: 作成：3営業日 (最大８営業日：第一次提出日までは３営業日、作業Excelレビューに3営業日、指摘反映＋反映確認に2営業日) | P14: 有(メール) ・レビューバック：3営業日 ・レビュー反映：２営業日 | Q14: 作業Excelを指定フォルダーに格納して提出 | R14: １カ月 【データ保持期限の確認対象】 １．生麦から提供している情報でoldに退避した分 (censusーold) (空気環境測定-old) (サーバルーム温度-old) ２．生麦の報告資料作成のための作業用情報（毎回作成して、バックアップしています） | S14: 手動 | T14: 作業提出メールと同時に完了報告を行う | U14: × | V14: × | W14: CF_WP | X14: 藤井さん（kenji.fujii） 齊藤さん（h.saito） 提出メール宛先／廣瀬さん（hirose.rio） | Z14: サービス停止 | AA14: 43770 | AB14: ー | AC14: FY24以前 | AD14: ー | AI14: ー | AJ14: ー | AK14: ー | AL14: ー | AM14: 45674 | AN14: 2019年11月より開始で、初回は2019/11/8に作業依頼として依頼元が、指定フォルダーに格納 2022年9月、サービス停止 | AO14: - | AS14: (サービス停止) | AT14: 9.対応不要 | AV14: 45785 | AY14: =IF(D14="受託",IF(COUNTA(B14,F14,G14:J14,Z14:AA14)=8,"OK","NG"),"確認対象外") -> OK | AZ14: =ISNUMBER(AJ14) -> FALSE | BA14: =ROW()-7 -> 7 | BB14: e
A15: =IF(Z15="サービス停止",Z15,"") -> サービス停止 | B15: A1008 | C15: =IF(B15="","-",IF(COUNTIF($B$8:B15,B15)=1,"〇","×")) -> 〇 | D15: 受託 | E15: SN_0008 | F15: 08データ集計・整形 | G15: WP_社内環境データ集計(サーバールーム温度) | H15: WPの社内環境データ集計として、サーバールーム温度を集計する。(対象ビル：7) | I15: 生麦 | J15: 生麦Y | K15: emiko.maeyama | L15: 無 | M15: 月次 | N15: 定常作業のため、無し (指定サイトに当月のデータを翌月の月初(第一営業日)にダウンロード) ※：作業者が指定サイトを確認し、ダウンロード | O15: 作成：3営業日 (最大８営業日：第一次提出日までは３営業日、作業Excelレビューに3営業日、指摘反映＋反映確認に2営業日) | P15: 有(メール) ・レビューバック：3営業日 ・レビュー反映：２営業日 | Q15: 作業Excelを指定フォルダーに格納して提出 | R15: １カ月 【データ保持期限の確認対象】 １．生麦から提供している情報でoldに退避した分 (censusーold) (空気環境測定-old) (サーバルーム温度-old) ２．生麦の報告資料作成のための作業用情報（毎回作成して、バックアップしています） | S15: 手動 | T15: 作業提出メールと同時に完了報告を行う | U15: × | V15: × | W15: CF_WP | X15: 藤井さん（kenji.fujii） 齊藤さん（h.saito） 提出メール宛先／廣瀬さん（hirose.rio） | Z15: サービス停止 | AA15: 43770 | AB15: ー | AC15: 45351 | AD15: ー | AI15: ー | AJ15: ー | AK15: ー | AL15: ー | AM15: 45674 | AN15: 2019年11月より開始。 2021年2月から拠点増(TSC)。8拠点→9拠点に変更。 2022年8月、対応7拠点に変更 2024/2/29：生麦Xへの移管に伴いサービス停止 | AO15: - | AS15: (サービス停止) | AT15: 9.対応不要 | AV15: 45785 | AY15: =IF(D15="受託",IF(COUNTA(B15,F15,G15:J15,Z15:AA15)=8,"OK","NG"),"確認対象外") -> OK | AZ15: =ISNUMBER(AJ15) -> FALSE | BA15: =ROW()-7 -> 8 | BB15: e
A16: =IF(Z16="サービス停止",Z16,"") -> サービス停止 | B16: A1009 | C16: =IF(B16="","-",IF(COUNTIF($B$8:B16,B16)=1,"〇","×")) -> 〇 | D16: 受託 | E16: SN_0009 | F16: 08データ集計・整形 | G16: WP_社内環境データ集計(空調設備) | H16: WPの社内環境データ集計として、空調測定結果を集計する。(対象ビル：8) | I16: 共通 | J16: 生麦Y 中津Y | K16: emiko.maeyama | L16: 無 | M16: 月次 | N16: 定常作業のため、無し (指定のフォルダーに当月のデータを翌月の月初(第一営業日)までに格納) | O16: 作成：3営業日 (最大８営業日：第一次提出日までは３営業日、作業Excelレビューに3営業日、指摘反映＋反映確認に2営業日) | P16: 有(メール) ・レビューバック：3営業日 ・レビュー反映：２営業日 | Q16: 作業Excelを指定フォルダーに格納して提出 | R16: １カ月 【データ保持期限の確認対象】 １．生麦から提供している情報でoldに退避した分 (censusーold) (空気環境測定-old) (サーバルーム温度-old) ２．生麦の報告資料作成のための作業用情報（毎回作成して、バックアップしています） | S16: 手動 | T16: 作業提出メールと同時に完了報告を行う | U16: × | V16: × | W16: CF_WP | X16: 藤井さん（kenji.fujii） 齊藤さん（h.saito） 提出メール宛先／廣瀬さん（hirose.rio） | Z16: サービス停止 | AA16: 43770 | AB16: ー | AC16: FY24以前 | AD16: ー | AI16: ー | AJ16: ー | AK16: ー | AL16: ー | AM16: 45674 | AN16: 2019年11月より開始 ベンダー情報が必要なため、依頼元で取得できない場合は、依頼がないことがある。2020年1月分より地方拠点3ビル追加。(作業は2月月初より)AIO及びAIFは奇数月分、AIHは偶数月分について作業。 2024/2/29：生麦Yに加え、中津Yも参画 2024/4/1 チーム移管に伴いサービス停止 | AO16: - | AS16: (サービス停止) | AT16: 9.対応不要 | AV16: 45785 | AY16: =IF(D16="受託",IF(COUNTA(B16,F16,G16:J16,Z16:AA16)=8,"OK","NG"),"確認対象外") -> OK | AZ16: =ISNUMBER(AJ16) -> FALSE | BA16: =ROW()-7 -> 9 | BB16: e
A17: =IF(Z17="サービス停止",Z17,"") -> サービス停止 | C17: =IF(B17="","-",IF(COUNTIF($B$8:B17,B17)=1,"〇","×")) -> - | D17: 受託 | E17: SN_0010 | G17: ACS_記事配信(各DTE) | H17: 各部署(DTE)の配信用記事のArticleのMedia Reportを作成する。 (SN_0006ではMCOMの特定記事だったが、本サービスでは複数部署) | I17: 生麦 | K17: akiko.a.hirano | L17: 無 | M17: 随時 | N17: リクエストフォーム | O17: 作成：5-10営業日 (最大10営業日：担当者の稼働状況に応じてリクエストフォームで納期提示する) | P17: 有(メール) レビューバック反映も実施する | Q17: 編集画面URLと画面キャプチャをメールで担当者に送付(公開したい方はURL、レビューのみしたい方はキャプチャでご確認頂く) | S17: 手動 | T17: 公開後にその旨メールで担当者にお知らせ(公開がご担当者の場合はレビュー後に完了) | U17: × | V17: 〇 ACS記事作成 （ACN.Collaboration.Services.Japan@accenture.comへメールにて依頼） | W17: HPS Delivery_Control AABG IES CSA ITO AMBG サービス依頼元：OK&DS 各記事の依頼元：Technology内の全組織 | X17: 米山さん（mizuki.yoneyama） 熊井さん（hitomi.kumai） ACN.Collaboration.Services.Japan@accenture.com | Z17: サービス停止 | AA17: 43801 | AB17: ー | AC17: FY24以前 | AD17: ー | AI17: ー | AJ17: ー | AK17: ー | AL17: ー | AM17: 45674 | AN17: 2019年12月2日より開始 「作業依頼から納期までのリードタイム」は5営業日にしていますが、依頼の件数が集中する場合も想定されますので、案件ごとに実施の可否判断。 2020年10月中旬より運用変更： 質問事項対応：確認リストに記入し、メールさせて頂く。リスト格納場所はメールに記載。(宛先：米山さん（mizuki.yoneyama）、CC: ACN.Collaboration.Services.Japan@accenture.com) 【対象DTE】 ・2019年時点実績：2DTE(CMT、RES) ・2020年1月中旬：PRD追加(月4-6記事程度) ・2020年2月：HPS追加 ・2020年5月：CMT(削除)、IES(追加) ・2020年6月：AABG ・2020年7月：CSA追加(月1記事程度) ・2020年8月：ITO追加(月1記事程度) ・2020年9月：AMBG追加(週3記事程度) ・2020年10月：Technology内の全組織（その他DTEは除外） 2021/1/1 から伊藤チーム対応へ変更(ST_0010) | AO17: - | AS17: (サービス停止) | AT17: 9.対応不要 | AV17: 45785 | AY17: =IF(D17="受託",IF(COUNTA(B17,F17,G17:J17,Z17:AA17)=8,"OK","NG"),"確認対象外") -> NG | AZ17: =ISNUMBER(AJ17) -> FALSE | BA17: =ROW()-7 -> 10 | BB17: e
A18: =IF(Z18="サービス停止",Z18,"") -> サービス停止 | C18: =IF(B18="","-",IF(COUNTIF($B$8:B18,B18)=1,"〇","×")) -> - | D18: 受託 | E18: SN_0011 | G18: Digital_マニュアルWeb化 | H18: DigitalのPPTマニュアルをTool(ホームページビルダー)にてWeb化 予定期間：2019/12/~2020/12/24 | I18: 生麦 | K18: hiroshi.a.harashima | L18: 無 | M18: 随時 | N18: 定常作業のため、無し (毎週水曜日に、次週分のWeb化マニュアルを格納) | O18: 該当週分を金曜日に指定フォルダーにアップロード | P18: 有(メール。必要に応じてCall) | Q18: Exportファイルを指定フォルダーに格納 | S18: 手動 | T18: 作業提出メールと同時に完了報告を行う | U18: 〇 | W18: Digital | X18: 内田さん（yuki.uchida） 清水さん（ryoichi.shimizu） 劉さん（dongqing.liu） | Z18: サービス停止 | AA18: 43800 | AB18: ー | AC18: FY24以前 | AD18: ー | AI18: ー | AJ18: ー | AK18: ー | AL18: ー | AM18: 45674 | AN18: 2019年12月よりテスト運用兼本番運用として開始し、2020年2月上旬までの予定。 →期間限定のため、「サービス停止」（本来は案件終了） | AO18: - | AS18: (サービス停止) | AT18: 9.対応不要 | AV18: 45785 | AY18: =IF(D18="受託",IF(COUNTA(B18,F18,G18:J18,Z18:AA18)=8,"OK","NG"),"確認対象外") -> NG | AZ18: =ISNUMBER(AJ18) -> FALSE | BA18: =ROW()-7 -> 11 | BB18: e
A19: =IF(Z19="サービス停止",Z19,"") -> サービス停止 | C19: =IF(B19="","-",IF(COUNTIF($B$8:B19,B19)=1,"〇","×")) -> - | D19: 受託 | E19: SN_0012 | G19: CCPMO_記事作成 | H19: CCPMOの配信用記事のArticleを作成する。 | I19: 生麦 | K19: akiko.a.hirano | L19: 無 | M19: 随時 | N19: リクエストフォーム | O19: 作成：４営業日 (最大６営業日：第一次提出日：4営業日、レビュー・指摘反映：2営業日) | P19: 有(メール) レビューバック反映も実施する | Q19: 編集画面URLをメールにて送付(TO：依頼者、CC：PMOのメーリス) | S19: 手動 | T19: 公開後にその旨メールでお知らせ | U19: × | X19: 栁谷さん（kikuko.yanagidani） | Z19: サービス停止 | AA19: 43822 | AB19: ー | AC19: FY24以前 | AD19: ー | AI19: ー | AJ19: ー | AK19: ー | AL19: ー | AM19: 45674 | AN19: 2019年12月23日より開始 →依頼元都合により、2020年8月に停止 | AO19: - | AS19: (サービス停止) | AT19: 9.対応不要 | AV19: 45785 | AY19: =IF(D19="受託",IF(COUNTA(B19,F19,G19:J19,Z19:AA19)=8,"OK","NG"),"確認対象外") -> NG | AZ19: =ISNUMBER(AJ19) -> FALSE | BA19: =ROW()-7 -> 12 | BB19: e
A20: =IF(Z20="サービス停止",Z20,"") -> サービス停止 | C20: =IF(B20="","-",IF(COUNTIF($B$8:B20,B20)=1,"〇","×")) -> - | D20: 受託 | E20: SN_0013 | G20: CCPMO_アサイン調整 | H20: CCPMOのアサイン調整の会議室確保とインビテーション送付する。 | I20: 生麦 | K20: akiko.a.hirano | L20: 無 | M20: 随時 | N20: リクエストフォーム | O20: 2営業日 | P20: 有(メール) レビューバック反映も実施する | Q20: インビテーション送付 | S20: 手動 | T20: インビテーション送付完了で対応完了とさせて頂く(再調整依頼メールがあった場合は対応) | U20: 〇 | X20: 栁谷さん（kikuko.yanagidani） | Z20: サービス停止 | AA20: 43822 | AB20: ー | AC20: FY24以前 | AD20: ー | AI20: ー | AJ20: ー | AK20: ー | AL20: ー | AM20: 45674 | AN20: 2019年12月23日より開始 2019/12/20時点では、日程調整はCCPMOの方に行って頂き、生麦での実施は別途検討。 →依頼元都合により、2020年8月に停止 | AO20: - | AS20: (サービス停止) | AT20: 9.対応不要 | AV20: 45785 | AY20: =IF(D20="受託",IF(COUNTA(B20,F20,G20:J20,Z20:AA20)=8,"OK","NG"),"確認対象外") -> NG | AZ20: =ISNUMBER(AJ20) -> FALSE | BA20: =ROW()-7 -> 13 | BB20: e
A21: =IF(Z21="サービス停止",Z21,"") -> サービス停止 | C21: =IF(B21="","-",IF(COUNTIF($B$8:B21,B21)=1,"〇","×")) -> - | D21: 受託 | E21: SN_0014 | G21: MCOM_記事配信(長編記事) | H21: MCOMの配信用記事の長編記事を作成する。 (Japan Information Site、いむじぇ 両方の対応あり) | I21: 生麦 | K21: akiko.a.hirano | L21: 無 | M21: 随時 | N21: リクエストフォーム (月2~3記事を想定) 原稿(編集画面URL記載頂く)・画像データをこちらに格納(フォルダ名「リクエストフォーム上のID_格納日」でフォルダを作成し格納 原稿のWordファイルを添付して頂く | O21: 作成：５営業日 (第一次提出日：５営業日、レビュー・指摘反映：なし) | P21: 無 (最終化は依頼元にて対応。ただし次回以降の改善につながるご指摘事項はメールにて共有頂く。) | Q21: 編集画面URLをメールで担当者に送付 | S21: 手動 | T21: 作業提出メールと同時に完了報告を行う | U21: × | V21: 〇 Wordpress （指定の申請書に直接記入で申請メールなし：備考欄参照） | W21: CF_MCOM | X21: 魚住さん（azusa.uozumi） IMJ担当者 村上さん（kumiko.murakami) | Z21: サービス停止 | AA21: 43844 | AB21: ー | AC21: FY24以前 | AD21: ー | AI21: ー | AJ21: ー | AK21: ー | AL21: ー | AM21: 45674 | AN21: 2020年1月14日より開始 2021/3/1 から、いむじぇサイトの記事依頼も受領開始 ■Japan information siteの「Editor」権限が必要。 下記申請フォームに入力。(いむじぇ分の登録も必要) https://ts.accenture.com/:x:/r/Sites/mcomjapan/_layouts/15/Doc.aspx?sourcedoc=%7B97EFB4A5-D615-4C87-B04E-09AAA524F65B%7D&file=ApplicationForm-EditingRightsForJIS_2020.xlsx&action=default&mobileredirect=true&cid=f148a7a4-b329-46fa-a3b0-6c1cb44c4d8b ※いむじぇ追加の場合IMJ側の担当者の情報もメモ欄に記入が必要。 2021/12/20 依頼が滞っていたため、依頼元に今後の依頼予定を確認したところ、当面長編記事依頼の見込みはございませんので 一旦取り下げていただいて結構ですとのこと。→クローズ。 | AO21: - | AS21: (サービス停止) | AT21: 9.対応不要 | AV21: 45785 | AY21: =IF(D21="受託",IF(COUNTA(B21,F21,G21:J21,Z21:AA21)=8,"OK","NG"),"確認対象外") -> NG | AZ21: =ISNUMBER(AJ21) -> FALSE | BA21: =ROW()-7 -> 14 | BB21: e
A22: =IF(Z22="サービス停止",Z22,"") -> サービス停止 | C22: =IF(B22="","-",IF(COUNTIF($B$8:B22,B22)=1,"〇","×")) -> - | D22: 受託 | E22: SN_0015 | G22: T-Pro_工数分析 | H22: T-Proの工数分析レポートを作成する。 | I22: 生麦 | K22: shigeki.ohtake | L22: 無 | M22: 月次 | N22: 期日が到来したら作業を開始する（作業トリガー：火曜日＠月末最終木曜週） ※月末最終木曜日が祝日を含む非営業日の場合、3営業日前から作業を開始する ※12月のみ 火曜日＠月末最終木曜週の前週対応 (依頼元にて、顧客の休日となるため) | O22: 作成：1.4営業日（以下の曜日で、祝日を含む非営業日がある場合は前営業日） 最大2.3営業日 ・第一次提出：1.4営業日(水曜日AM@月末最終木曜週) ・レビュー・指摘反映：0.9営業日(木曜日AM11時@月末最終木曜週まで) ※「木曜PM以降に修正が必要となった場合」及び「AM11時までに修正が完了しない場合」、プロジェクト側で巻き取っていただく | P22: 有(メール) レビューバック反映も実施する | Q22: 作業ファイルを指定フォルダーに格納してメールにて提出報告 | R22: 依頼元：指定なし 内部処理：納品物のみ保存、期間は指定なし | S22: 手動 | T22: 「レビュー反映後の納品物を格納」又は「確認完了メール受領」をもって完了とする | U22: 〇 | V22: × | W22: Technology | X22: 桑崎さん（norimi.kuwasaki） | Z22: サービス停止 | AA22: 43886 | AB22: ー | AC22: FY24以前 | AD22: ー | AI22: ー | AJ22: ー | AK22: ー | AL22: ー | AM22: 45674 | AN22: 2020年2月25日より開始 (対象レコードは万単位) 2022/7月にて業務終了 | AO22: - | AS22: (サービス停止) | AT22: 9.対応不要 | AV22: 45785 | AY22: =IF(D22="受託",IF(COUNTA(B22,F22,G22:J22,Z22:AA22)=8,"OK","NG"),"確認対象外") -> NG | AZ22: =ISNUMBER(AJ22) -> FALSE | BA22: =ROW()-7 -> 15 | BB22: e
A23: =IF(Z23="サービス停止",Z23,"") -> サービス停止 | B23: A1016 | C23: =IF(B23="","-",IF(COUNTIF($B$8:B23,B23)=1,"〇","×")) -> 〇 | D23: 受託 | E23: SN_0016 | F23: 07入力・登録代行 | G23: T-Pro_RedmineID追加 | H23: T-ProのRedmineIDを登録し、ID発行メールを送信する。 | I23: 生麦 | J23: 生麦X | K23: shigeki.ohtake | L23: 無 | M23: 随時 | N23: リクエストフォーム (アサイン情報のメールを添付) | O23: 登録：2営業日(リクエストフォーム依頼の翌営業日から2営業日) 最大5営業日 ・第一次提出：2営業日 ・レビュー・指摘反映：3営業日 ※IDの作成は5営業日だが、ID発行メールは対象者別にアサイン日から5営業日以内にメールする ID登録・ID発行メール：対象者別にアサイン日から5営業日以内にメール送信できるようにIDを登録する。 | P23: 有(メール) レビューバック反映も実施する 無 (但し、不備があった場合はメールでの指摘有り。反映も実施する。) | Q23: 作業ファイルを指定フォルダーに格納してメールにて提出報告 PJTアサイン対象者本人にID発行メールを送信 | R23: 過去３カ月もしくは過去３回分を保持。(2022/02/24確認リストにて依頼元了承) | S23: 手動 | T23: 作業完了およびレビュー反映をもって完了とする ※ID発行メールは対象者別にアサイン日から5営業日以内にメールし完了とする | U23: 〇 | V23: × | W23: Technology | X23: 王さん（dan.wang） 桑崎さん（norimi.kuwasaki） | Z23: =IF(AC23="",IF(AA23="","",IF(TODAY()>=AA23,"サービス開始",IF(TODAY()<AA23,"本稼働前",""))),IF(TODAY()>=AC23,"サービス停止",IF(AA23="","",IF(TODAY()>=AA23,"サービス開始",IF(TODAY()<AA23,"本稼働前",""))))) -> サービス停止 | AA23: 43886 | AB23: ー | AC23: 45970 | AD23: ー | AG23: T-Pro_RedmineID追加 | AI23: Technology | AJ23: 1 | AK23: ー | AL23: ー | AM23: 45674 | AN23: 2025/10/7：サービス終了。WDMの更新未対応であったため、サービス停止に変更 2020年2月25日より開始 2020年9月より運用変更（依頼元からの要請） ・ID登録後の作業完了メールは不要 ・ID登録はアサイン日から5営業日以内のID発行メールに間に合うように実施することでOK ・2022・6～生麦Yから生麦Xへ業務移管 | AO23: - | AQ23: A_通常_決定(登録可) | AS23: 登録済_本登録 | AT23: 4b.本登録_計測方法確定(FY24以前) | AV23: 45785 | AW23: ('25/10/7)サービス停止に変更 | AY23: =IF(D23="受託",IF(COUNTA(B23,F23,G23:J23,Z23:AA23)=8,"OK","NG"),"確認対象外") -> OK | AZ23: =ISNUMBER(AJ23) -> TRUE | BA23: =ROW()-7 -> 16 | BB23: e
A24: =IF(Z24="サービス停止",Z24,"") | B24: A1017 | C24: =IF(B24="","-",IF(COUNTIF($B$8:B24,B24)=1,"〇","×")) -> 〇 | D24: 受託 | E24: SN_0017 | F24: 01調査・結果纏め | G24: HPS_教育・大学ニュース関連配信作業 | H24: HPS用の教育・大学ニュース関連記事を検索し配信する作業 | I24: 生麦 | J24: 生麦Y | K24: atsushi.b.yamamoto | L24: 無 | M24: 週次 | N24: 期日が到来したら作業を開始する （作業トリガー：月曜日、祝日の場合は次営業日） | O24: 検索：2営業日 最大3営業日（以下の曜日で、祝日がある場合は次営業日） ・第一次提出：2営業日（月曜日～火曜日） ・レビュー・指摘反映・ ニュース配信：1営業日（水曜日） | P24: 有(メール) 作業ファイル・配信メールテキスト本文を確認し、指摘事項をメール返信にてご連絡いただく | Q24: 作業ファイル・配信用メールテキスト本文を、指定フォルダに格納して、メールにて提出報告 | R24: 3か月 ※2022.4.15確認済 | S24: 手動 | T24: 「ニュース配信」をもって完了とする | U24: × | V24: × | W24: HPS | X24: 今井さん（shingo.imai） | Z24: =IF(AC24="",IF(AA24="","",IF(TODAY()>=AA24,"サービス開始",IF(TODAY()<AA24,"本稼働前",""))),IF(TODAY()>=AC24,"サービス停止",IF(AA24="","",IF(TODAY()>=AA24,"サービス開始",IF(TODAY()<AA24,"本稼働前",""))))) -> サービス開始 | AA24: 43920 | AB24: ー | AI24: Technology | AJ24: 1 | AK24: ー | AL24: ー | AM24: 45674 | AN24: 2020年3月30日より開始 2020年4月6日より運用変更（依頼元との認識違いによりマニュアル等変更必要） ・第一次提出：2営業日 ・レビュー・指摘反映・ ニュース配信：1営業日 →第一次提出時にレビュー依頼なしでニュース配信 に変更 2024/6/17：依頼元担当者が「大久保さん（chikara.ohkubo）」から「今井さん（shingo.imai）」変更。 2024/7/1：担当SV変更＞emiko.maeyama ➡ atsushi.b.yamamoto | AO24: - | AQ24: A_通常_決定(登録可) | AS24: 登録済_本登録 | AT24: 4b.本登録_計測方法確定(FY24以前) | AV24: 45785 | AY24: =IF(D24="受託",IF(COUNTA(B24,F24,G24:J24,Z24:AA24)=8,"OK","NG"),"確認対象外") -> OK | AZ24: =ISNUMBER(AJ24) -> TRUE | BA24: =ROW()-7 -> 17 | BB24: e
A25: =IF(Z25="サービス停止",Z25,"") -> サービス停止 | C25: =IF(B25="","-",IF(COUNTIF($B$8:B25,B25)=1,"〇","×")) -> - | D25: 受託 | E25: SN_0018 | G25: Digital_マイナポレスポンシブ | H25: Digitalの次期マイナポ再構築として、レスポンシブ対応 | I25: 生麦 | K25: hiroshi.a.harashima | L25: 無 | M25: 随時 | N25: 設計書・モック等必要ファイルを指定フォルダに格納のうえ、Teamsにてメンションいただく | O25: 提示スケジュールにもとづき対応とする。納期遅延の見込みが発生した場合は、至急相談のうえ調整させていただく。 | P25: レビュー結果一覧に結果を記載いただき、指定フォルダに格納して、Teamsメンションにて返信いただく | Q25: レスポンシブ化済みHTMLファイル/レビューチェックシート/テスト結果一覧を、指定フォルダに格納して、Teamsメンションにて提出報告 | S25: 手動 | T25: レビュー結果一覧で指摘なしの旨のレビューバックをもって完了とする | U25: 〇 | V25: × | W25: Digital | X25: 内田さん（yuki.uchida） 清水さん（ryoichi.shimizu） 劉さん（dongqing.liu） | Z25: サービス停止 | AA25: 43941 | AB25: ー | AC25: FY24以前 | AD25: ー | AI25: ー | AJ25: ー | AK25: ー | AL25: ー | AM25: 45674 | AN25: 2020年4月20日より開始 スケジュール・作業量は、依頼元スケジュールにより、変動することがある。 また、週次で依頼元と状況確認。 | AO25: - | AS25: (サービス停止) | AT25: 9.対応不要 | AV25: 45785 | AY25: =IF(D25="受託",IF(COUNTA(B25,F25,G25:J25,Z25:AA25)=8,"OK","NG"),"確認対象外") -> NG | AZ25: =ISNUMBER(AJ25) -> FALSE | BA25: =ROW()-7 -> 18 | BB25: e
A26: =IF(Z26="サービス停止",Z26,"") -> サービス停止 | B26: A1019 | C26: =IF(B26="","-",IF(COUNTIF($B$8:B26,B26)=1,"〇","×")) -> 〇 | D26: 受託 | E26: SN_0019 | F26: 01調査・結果纏め | G26: 人事異動・メディアリリース情報チェック | H26: 人事異動・メディアリリースニュース関連記事を検索し配信する作業 | I26: 共通 | J26: 生麦Y 中津Y | K26: emiko.maeyama | L26: 無 | M26: 週次 | N26: 期日が到来したら作業を開始する （作業トリガー：月曜日、祝日の場合は次営業日） | O26: 検索：3営業日 （以下の曜日で、祝日がある場合は次営業日） ・第一次提出：3営業日（月曜日～水曜日） | P26: 無 (但し、入力不備があった場合はメールでの指摘有り) | Q26: 作業ファイルを、メールに添付して提出報告 | R26: 3か月 ※2022.4.15確認済 | S26: 手動 | T26: メール配信連絡をもって完了とする | U26: 〇 | V26: × | W26: RES | X26: 竹村さん（ryo.takemura） 吉松さん（yuriko.yoshimatsu） | Z26: サービス停止 | AA26: 43990 | AB26: ー | AC26: FY24以前 | AD26: ー | AI26: ー | AJ26: ー | AK26: ー | AL26: ー | AM26: 45674 | AN26: 2020年6月8日より開始 2024/2/29：生麦Yに加え、中津Yも参画 2024/4/22：チーム移管に伴いサービス停止 | AO26: - | AS26: (サービス停止) | AT26: 9.対応不要 | AV26: 45785 | AY26: =IF(D26="受託",IF(COUNTA(B26,F26,G26:J26,Z26:AA26)=8,"OK","NG"),"確認対象外") -> OK | AZ26: =ISNUMBER(AJ26) -> FALSE | BA26: =ROW()-7 -> 19 | BB26: e
A27: =IF(Z27="サービス停止",Z27,"") | B27: A1020 | C27: =IF(B27="","-",IF(COUNTIF($B$8:B27,B27)=1,"〇","×")) -> 〇 | D27: 受託 | E27: SN_0020 | F27: 91TBD_仮登録 | G27: RES_SharePointデータ移行 | H27: RESの日東電工PJTが持つ複数Sharepoint間でのファイル・フォルダ移行作業 | I27: 生麦 | J27: 生麦X | K27: shigeki.ohtake | L27: 無 | M27: 随時 | N27: リクエストフォーム | O27: 2週間 | P27: 有 指摘があれば、指摘事項と共に対応が必要か、メール返信にてご連絡いただく | Q27: 作業結果をメールに添付して報告 | R27: 依頼元：指定なし | S27: 手動 | T27: 作業結果を添付したメールの配信を以て完了 | U27: 〇 | V27: × | W27: RES | X27: 月岡さん（ryosuke.tsukioka） NTD.PMO.Adm@accenture.com | Z27: =IF(AC27="",IF(AA27="","",IF(TODAY()>=AA27,"サービス開始",IF(TODAY()<AA27,"本稼働前",""))),IF(TODAY()>=AC27,"サービス停止",IF(AA27="","",IF(TODAY()>=AA27,"サービス開始",IF(TODAY()<AA27,"本稼働前",""))))) -> サービス開始 | AA27: 43997 | AB27: ー | AG27: RES_SharePointデータ移行 | AI27: Technology | AJ27: 1 | AK27: ー | AL27: ー | AM27: 45674 | AN27: サービス開始後依頼なし | AO27: - | AQ27: C_通常_未定(仮登録可) | AS27: 登録済_仮登録 | AT27: 2b.仮登録_計測方法未定(FY24以前) | AV27: 45785 | AY27: =IF(D27="受託",IF(COUNTA(B27,F27,G27:J27,Z27:AA27)=8,"OK","NG"),"確認対象外") -> OK | AZ27: =ISNUMBER(AJ27) -> TRUE | BA27: =ROW()-7 -> 20 | BB27: e
A28: =IF(Z28="サービス停止",Z28,"") -> サービス停止 | C28: =IF(B28="","-",IF(COUNTIF($B$8:B28,B28)=1,"〇","×")) -> - | D28: 受託 | E28: SN_0021 | G28: PRD_人事異動・組織改編情報チェック(優先50社) | H28: PRDのクライアント50社の人事異動情報・組織改編情報を検索し、配信する作業 | I28: 生麦 | K28: akiko.a.hirano | L28: 無 | M28: 週次 | N28: 期日が到来したら作業を開始する (作業トリガー: 毎週第一営業日) | O28: 最大6営業日 | P28: 無 (但し、入力不備があった場合はメールでの指摘有り) | Q28: 作業ファイルをメールに添付して報告 | S28: 手動 | T28: 作業ファイルを添付したメールの配信を以て完了 | U28: 〇 | V28: × | W28: PRD | X28: 山口さん（kunishige.yamaguchi） | Z28: サービス停止 | AA28: 43990 | AB28: ー | AC28: FY24以前 | AD28: ー | AI28: ー | AJ28: ー | AK28: ー | AL28: ー | AM28: 45674 | AN28: 2020年6月8日より開始 SN_0025に置き換え | AO28: - | AS28: (サービス停止) | AT28: 9.対応不要 | AV28: 45785 | AY28: =IF(D28="受託",IF(COUNTA(B28,F28,G28:J28,Z28:AA28)=8,"OK","NG"),"確認対象外") -> NG | AZ28: =ISNUMBER(AJ28) -> FALSE | BA28: =ROW()-7 -> 21 | BB28: e
A29: =IF(Z29="サービス停止",Z29,"") | B29: A1022 | C29: =IF(B29="","-",IF(COUNTIF($B$8:B29,B29)=1,"〇","×")) -> 〇 | D29: 受託 | E29: SN_0022 | F29: 03サニタイズ編集 | G29: RES_KXサニタイズ代行 | H29: RESから依頼された日東電工PJTドキュメントをKXに登録可能な フォーマットに修正する。 | I29: 生麦 | J29: TF | K29: tomoyuki.a.hishiki | L29: 無 | M29: 随時 | N29: リクエストフォーム | O29: 一次提出：3週間 納期:4週間 | P29: 有(メール) レビューバック反映も実施する | Q29: SharePoint上の個別フォルダ (権限設定有り) | S29: 手動 | T29: ・アップロード完了連絡 | U29: 〇 | V29: × | W29: AS_RES | X29: 吉松さん（yuriko.yoshimatsu） | Z29: =IF(AC29="",IF(AA29="","",IF(TODAY()>=AA29,"サービス開始",IF(TODAY()<AA29,"本稼働前",""))),IF(TODAY()>=AC29,"サービス停止",IF(AA29="","",IF(TODAY()>=AA29,"サービス開始",IF(TODAY()<AA29,"本稼働前",""))))) -> サービス開始 | AA29: 44004 | AB29: ー | AG29: RES_KXサニタイズ代行 | AH29: ①A1023 ②A1022 | AI29: Technology | AJ29: 1 | AK29: ー | AL29: ー | AM29: 45674 | AN29: 2020年6月22日より開始 2021/10/1より、担当SV変更：Maeyama→（Takahashi,Airi)→Ito 2022/05/15より、担当SV変更：Ito→Watanabe 2023/3/1より、担当SV変更：koji.c.watanabe→hiroyuki.hishiki | AO29: - | AQ29: A_通常_決定(登録可) | AS29: 登録済_本登録 | AT29: 4b.本登録_計測方法確定(FY24以前) | AV29: 45785 | AY29: =IF(D29="受託",IF(COUNTA(B29,F29,G29:J29,Z29:AA29)=8,"OK","NG"),"確認対象外") -> OK | AZ29: =ISNUMBER(AJ29) -> TRUE | BA29: =ROW()-7 -> 22 | BB29: e
A30: =IF(Z30="サービス停止",Z30,"") | B30: A1023 | C30: =IF(B30="","-",IF(COUNTIF($B$8:B30,B30)=1,"〇","×")) -> 〇 | D30: 受託 | E30: SN_0023 | F30: 02サニタイズ編集要件 | G30: RES_WordList作成作業(KXサニタイズ代行) | H30: RESから依頼された日東電工PJTドキュメントの、KXサニタイズに必要なWordListを作成する。 | I30: 生麦 | J30: TF | K30: tomoyuki.a.hishiki | L30: 無 | M30: 随時 | N30: リクエストフォーム | O30: 一次提出：3週間 納期:4週間 | P30: 有(メール) レビューバック反映も実施する | Q30: SharePoint上の個別フォルダ (権限設定有り) | S30: 手動 | T30: ・アップロード完了連絡 | U30: 〇 | V30: × | W30: AS_RES | X30: 吉松さん（yuriko.yoshimatsu） | Z30: =IF(AC30="",IF(AA30="","",IF(TODAY()>=AA30,"サービス開始",IF(TODAY()<AA30,"本稼働前",""))),IF(TODAY()>=AC30,"サービス停止",IF(AA30="","",IF(TODAY()>=AA30,"サービス開始",IF(TODAY()<AA30,"本稼働前",""))))) -> サービス開始 | AA30: 44004 | AB30: ー | AG30: RES_KXサニタイズ代行 | AH30: ①A1023 ②A1022 | AI30: Technology | AJ30: 1 | AK30: ー | AL30: ー | AM30: 45674 | AN30: 基本的に、0022と0023が別に依頼されることはないが、作業は分かれるためそれぞれサービス管理番号を設定。 2021/10/1より、担当SV変更：Maeyama→（Takahashi,Airi)→Ito 2022/05/15より、担当SV変更：Ito→Watanabe 2023/3/1より、担当SV変更：koji.c.watanabe→hiroyuki.hishiki | AO30: - | AQ30: A_通常_決定(登録可) | AS30: 登録済_本登録 | AT30: 4b.本登録_計測方法確定(FY24以前) | AV30: 45785 | AY30: =IF(D30="受託",IF(COUNTA(B30,F30,G30:J30,Z30:AA30)=8,"OK","NG"),"確認対象外") -> OK | AZ30: =ISNUMBER(AJ30) -> TRUE | BA30: =ROW()-7 -> 23 | BB30: e
A31: =IF(Z31="サービス停止",Z31,"") -> サービス停止 | B31: A1024 | C31: =IF(B31="","-",IF(COUNTIF($B$8:B31,B31)=1,"〇","×")) -> 〇 | D31: 受託 | E31: SN_0024 | F31: 10回答作成 | G31: Digital_マイナポWeb問合せ回答 | H31: 国民からマイナポータルへ届く、お問い合わせへの回答を作成する業務 | I31: 生麦 | J31: 生麦X | K31: shigeki.ohtake | L31: 無 | M31: 日次 | N31: 定常作業のため、無し (毎日朝9:30に、当日の作業量を確認) | O31: 問い合わせ一覧作成：当日10:00まで 回答入力: 当日11:00まで 回答案作成: 当日15:00まで | P31: 有 提出した翌日にいただける想定 | Q31: 依頼元とのTeams上の個別フォルダ | R31: 依頼元：指定なし 内部処理：納品物のみ保存、期間は指定なし | S31: 手動 | T31: Teamsにて連絡 | U31: × | V31: × | W31: Digital | X31: 宮嶋さん（tatsuya.miyajima） 安部さん（yoshiaki.abe） | Z31: =IF(AC31="",IF(AA31="","",IF(TODAY()>=AA31,"サービス開始",IF(TODAY()<AA31,"本稼働前",""))),IF(TODAY()>=AC31,"サービス停止",IF(AA31="","",IF(TODAY()>=AA31,"サービス開始",IF(TODAY()<AA31,"本稼働前",""))))) -> サービス停止 | AA31: 44032 | AB31: ー | AC31: 45291 | AD31: ー | AG31: Digital_マイナポWeb問合せ回答 | AI31: ー | AJ31: ー | AK31: ー | AL31: ー | AM31: 45674 | AN31: 2020年7月20日より開始 | AO31: - | AS31: (サービス停止) | AT31: 9.対応不要 | AV31: 45785 | AY31: =IF(D31="受託",IF(COUNTA(B31,F31,G31:J31,Z31:AA31)=8,"OK","NG"),"確認対象外") -> OK | AZ31: =ISNUMBER(AJ31) -> FALSE | BA31: =ROW()-7 -> 24 | BB31: e
A32: =IF(Z32="サービス停止",Z32,"") | B32: A1025 | C32: =IF(B32="","-",IF(COUNTIF($B$8:B32,B32)=1,"〇","×")) -> 〇 | D32: 受託 | E32: SN_0025 | F32: 01調査・結果纏め | G32: 人事異動・組織改編情報チェック(自動化) | H32: PRDのクライアント459社の人事異動情報・組織改編情報を自動化ツール(UiPath)を使用して検索し、一覧にまとめて配信する作業 | I32: 生麦 | J32: 生麦X | K32: shigeki.ohtake | L32: 無 | M32: 週次 | N32: 期日が到来したら作業を開始する (作業トリガー: 毎週第一営業日) | O32: 最大6営業日 | P32: 無 (但し、入力不備があった場合はメールでの指摘有り) | Q32: 作業ファイルをメールに添付して報告 | R32: 依頼元：指定なし 内部処理：納品物のみ保存、期間は指定なし | S32: 手動 | T32: 作業ファイルを添付したTeamsの配信を以て完了 | U32: 〇 | V32: × | W32: PRD | X32: 山口さん（kunishige.yamaguchi） | Z32: =IF(AC32="",IF(AA32="","",IF(TODAY()>=AA32,"サービス開始",IF(TODAY()<AA32,"本稼働前",""))),IF(TODAY()>=AC32,"サービス停止",IF(AA32="","",IF(TODAY()>=AA32,"サービス開始",IF(TODAY()<AA32,"本稼働前",""))))) -> サービス開始 | AA32: 44075 | AB32: ー | AG32: 人事異動・組織改編情報チェック(自動化) | AI32: Client Service Group | AJ32: 1 | AK32: ー | AL32: ー | AM32: 45674 | AN32: SN_0021の自動化後の案件(置き換え) 2020年9月中旬のサービス開始を想定 | AO32: - | AQ32: A_通常_決定(登録可) | AS32: 登録済_本登録 | AT32: 4b.本登録_計測方法確定(FY24以前) | AV32: 45785 | AY32: =IF(D32="受託",IF(COUNTA(B32,F32,G32:J32,Z32:AA32)=8,"OK","NG"),"確認対象外") -> OK | AZ32: =ISNUMBER(AJ32) -> TRUE | BA32: =ROW()-7 -> 25 | BB32: e
A33: =IF(Z33="サービス停止",Z33,"") -> サービス停止 | C33: =IF(B33="","-",IF(COUNTIF($B$8:B33,B33)=1,"〇","×")) -> - | D33: 受託 | E33: SN_0026 | G33: Operations_ファミ通Collections登録 | H33: Operations本部内で送信されているファミリー通信(ファミ通)をCollectionsに登録する作業 | I33: 生麦 | K33: shigeki.ohtake | L33: 無 | M33: 隔週 | N33: リクエストフォーム | O33: リクエストフォームでの依頼から5営業日 （隔週金曜に依頼→翌週金曜が納期） | P33: 無 (但し、入力不備があった場合はメールでの指摘有り) | Q33: 提出はなし (Collectionsに登録することが業務) | R33: 依頼元：指定なし 内部処理：納品物のみ保存、期間は指定なし | S33: 手動 | T33: メールでの完了報告 | U33: × | V33: 〇 Collectionsへのアクセス権限付与依頼が必要(メール) | W33: Operations | X33: 遠藤さん（mai.endo） | Z33: サービス停止 | AA33: 44043 | AB33: ー | AC33: FY24以前 | AD33: ー | AI33: ー | AJ33: ー | AK33: ー | AL33: ー | AM33: 45674 | AN33: 2020/7/31より開始 2022/6より依頼元サイト閉鎖のため、終了 | AO33: - | AS33: (サービス停止) | AT33: 9.対応不要 | AV33: 45785 | AY33: =IF(D33="受託",IF(COUNTA(B33,F33,G33:J33,Z33:AA33)=8,"OK","NG"),"確認対象外") -> NG | AZ33: =ISNUMBER(AJ33) -> FALSE | BA33: =ROW()-7 -> 26 | BB33: e
